Workbook

Sheet Read Me
A4: Project Sahel Sun — 50MW Solar IPP: Capital Stack & Debt Sizing Template
A6: MIPF Boot Camp, Day 1 — Infrastructure Finance: Structuring, Risk Management & Sustainable Project Delivery (14 October 2026)
A7: Facilitator: Prof. Bongo Adi, Lagos Business School, Pan-Atlantic University
A9: HOW TO USE
A10: 1. Go to 'Inputs'. Change only BLUE cells. YELLOW cells are the key levers used in the workshop exercises.
A11: 2. 'Capital Stack' shows Uses and Sources of funds, gearing and the layered stack. Debt is sized automatically.
A12: 3. 'CashFlow_Debt' builds CFADS, sizes debt by DSCR sculpting, and reports DSCR, LLCR and equity IRR.
A13: 4. Stress-test the deal with the scenario levers (naira depreciation, FX pass-through, offtaker payment rate, P90 output, opex overrun).
A14: Lenders SIZE debt on the base case; the stress levers then show what happens to DSCR once the debt is fixed.
A16: COLOUR CODE: Blue text = input · Black = formula · Green = link from another sheet · Yellow fill = key exercise lever
A17: UNITS: US$ millions unless stated. Model is annual, 20-year operations, construction collapsed to Year 0 for teaching simplicity.
A19: IMPORTANT: Project Sahel Sun is a fictional teaching case. All numbers are illustrative, chosen to be realistic for a Nigerian utility-scale
... A24: Adapted from the CIBN Centre for Financial Studies workshop (facilitator: Prof. Bongo Adi). Teaching case; all figures illustrative.

Sheet Inputs
A1: Inputs & Assumptions
A3: TECHNICAL
A4: Installed capacity (MWac) | B4: 50 | C4: MW | D4: Project Sahel Sun, Kano State (fictional)
A5: Net capacity factor (P50) | B5: 0.21 | C5: % | D5: Northern Nigeria irradiation supports ~19-23% for single-axis/fixed PV; illustrative
A6: Annual degradation | B6: 0.005 | C6: % | D6: Typical panel warranty assumption
A7: Operating life modelled (years) | B7: 20 | C7: yrs | D7: Equal to the PPA term
A8: REVENUE
A9: PPA tariff (US$/MWh, dollar-indexed) | B9: 95 | C9: $/MWh | D9: Illustrative; paid in naira at prevailing CBN rate if pass-through = 100%
A10: COSTS
A11: Opex year 1 (US$m) | B11: 1.1 | C11: $m | D11: O&M, insurance, land lease, security, admin
A12: Opex escalation | B12: 0.02 | C12: % | D12: US$ inflation-linked
A13: Corporate income tax rate | B13: 0.3 | C13: % | D13: Illustrative; confirm current CIT rate for the project's size
A14: Tax holiday (pioneer status) years | B14: 5 | C14: yrs | D14: Pioneer status incentive; illustrative
A15: Depreciation life (years) | B15: 20 | C15: yrs | D15: Straight-line, simplified capital allowances
A16: USES OF FUNDS (US$m)
A17: EPC contract (modules, inverters, BoS) | B17: 44 | C17: $m
A18: Development costs, permits, land, ESIA | B18: 3 | C18: $m
A19: Grid connection / evacuation line | B19: 3.5 | C19: $m | D19: Often a TCN-interface risk item
A20: Financing fees & interest during construction | B20: 3 | C20: $m
A21: Initial DSRA funding | B21: 1.5 | C21: $m | D21: Debt Service Reserve Account
A22: FINANCING TERMS
A23: Target minimum DSCR (base case) | B23: 1.35 | C23: x | D23: Lenders' sizing covenant; solar with creditworthy offtaker 1.25-1.40x
A24: Maximum gearing (debt / total cost) | B24: 0.7 | C24: % | D24: Lenders' cap
A25: Senior debt tenor (years) | B25: 15 | C25: yrs
A26: Blended senior interest rate (US$-equivalent) | B26: 0.1 | C26: % | D26: Mix of DFI US$ loan and InfraCredit-guaranteed naira bond; illustrative
A27: Share of senior debt: DFI US$ loan | B27: 0.6 | C27: % | D27: Remainder = InfraCredit-guaranteed local-currency green bond
A28: Share of equity funded as shareholder loan | B28: 0.5 | C28: % | D28: Sub-debt from sponsors; rest ordinary shares
A29: SCENARIO LEVERS (set to base values for the base case)
A30: Naira depreciation after financial close | B30: 0 | C30: % | D30: Exercise lever. e.g. 0.30 = naira loses 30% vs US$
A31: Tariff FX pass-through | B31: 1 | C31: % | D31: Exercise lever. 1.0 = tariff fully dollar-indexed; 0.5 = only half indexed
A32: Offtaker payment rate (collections) | B32: 1 | C32: % | D32: Exercise lever. 0.8 = offtaker pays only 80% of invoices
A33: Generation haircut (e.g. P90 vs P50) | B33: 0 | C33: % | D33: Exercise lever. 0.08 ≈ P90 case
A34: Opex overrun | B34: 0 | C34: % | D34: Exercise lever

Sheet Capital Stack
A1: Capital Stack — Uses & Sources of Funds (US$m)
A3: USES OF FUNDS | B3: US$m | C3: % total
A4: EPC contract (modules, inverters, BoS) | B4: =Inputs!$B$17 -> 44 | C4: =B4/$B$9 -> 0.8
A5: Development costs, permits, land, ESIA | B5: =Inputs!$B$18 -> 3 | C5: =B5/$B$9 -> 0.054545455
A6: Grid connection / evacuation line | B6: =Inputs!$B$19 -> 3.5 | C6: =B6/$B$9 -> 0.063636364
A7: Financing fees & interest during construction | B7: =Inputs!$B$20 -> 3 | C7: =B7/$B$9 -> 0.054545455
A8: Initial DSRA funding | B8: =Inputs!$B$21 -> 1.5 | C8: =B8/$B$9 -> 0.027272727
A9: Total project cost | B9: =SUM(B4:B8) -> 55 | C9: =SUM(C4:C8) -> 1
A11: DEBT SIZING (from CashFlow_Debt)
A12: Debt capacity at target DSCR (PV of sculpted debt service) | B12: =CashFlow_Debt!$C$30 -> 37.402145 | D12: Lenders ask: how much debt can the cash flow carry?
A13: Debt allowed by gearing cap | B13: =B9*Inputs!$B$24 -> 38.5 | D13: Lenders ask: how much skin does the sponsor have in the game?
A14: Senior debt raised = MIN(DSCR capacity, gearing cap) | B14: =MIN(B12,B13) -> 37.402145
A15: Binding constraint | B15: =IF(B12<=B13,"DSCR","Gearing") -> DSCR
A17: SOURCES OF FUNDS (the capital stack, most senior first) | B17: US$m | C17: % total | D17: Typical provider / pricing logic
A18: Senior A — DFI US$ term loan | B18: =B14*Inputs!$B$27 -> 22.441287 | C18: =B18/$B$22 -> 0.4080234 | D18: e.g. IFC, AfDB, FMO, BII; 15-yr, hard currency
A19: Senior B — InfraCredit-guaranteed naira green bond | B19: =B14*(1-Inputs!$B$27) -> 14.960858 | C19: =B19/$B$22 -> 0.2720156 | D19: Pension funds / insurers; AAA(NG) wrap, local currency
A20: Shareholder loan (subordinated) | B20: =(B9-B14)*Inputs!$B$28 -> 8.7989276 | C20: =B20/$B$22 -> 0.1599805 | D20: Sponsors; paid after senior debt service
A21: Ordinary equity | B21: =(B9-B14)*(1-Inputs!$B$28) -> 8.7989276 | C21: =B21/$B$22 -> 0.1599805 | D21: Sponsors / infrastructure funds; first loss
A22: Total sources | B22: =SUM(B18:B21) -> 55 | C22: =SUM(C18:C21) -> 1
A23: Check: sources − uses (must be zero) | B23: =B22-B9 -> 0
A25: KEY RATIOS
A26: Gearing (senior debt / total cost) | B26: =B14/B9 -> 0.680039
A27: Sponsor funding (equity + shareholder loan) / total cost | B27: =(B20+B21)/B9 -> 0.319961
A28: Minimum DSCR (current scenario) | B28: =CashFlow_Debt!$C$47 -> 1.35
A29: Average DSCR (current scenario) | B29: =CashFlow_Debt!$C$48 -> 1.35
A30: LLCR at financial close (current scenario) | B30: =CashFlow_Debt!$C$49 -> 1.35
A31: Equity IRR — sponsor funds, 20 yrs (current scenario) | B31: =CashFlow_Debt!$C$52 -> 0.10253898
A32: Years with DSCR below 1.0x (default on debt service) | B32: =CashFlow_Debt!$C$50 -> 0

Sheet CashFlow_Debt
A1: Cash Flow Available for Debt Service (CFADS), Debt Sculpting & Cover Ratios (US$m)
A3: Line item | B3: Unit | C3: Total / key | D3: Yr 1 | E3: Yr 2 | F3: Yr 3 | G3: Yr 4 | H3: Yr 5 | I3: Yr 6 | J3: Yr 7 | K3: Yr 8 | L3: Yr 9 | M3: Yr 10 | N3: Yr 11 | O3: Yr 12 | P3: Yr 13 | Q3: Yr 14 | R3: Yr 15 | S3: Yr 16 | T3: Yr 17 | U3: Yr 18 | V3: Yr 19 | W3: Yr 20
A4: Operating year | D4: 1 | E4: 2 | F4: 3 | G4: 4 | H4: 5 | I4: 6 | J4: 7 | K4: 8 | L4: 9 | M4: 10 | N4: 11 | O4: 12 | P4: 13 | Q4: 14 | R4: 15 | S4: 16 | T4: 17 | U4: 18 | V4: 19 | W4: 20
A5: BASE CASE (used by lenders to SIZE the debt)
A6: Net generation (P50) | B6: MWh | D6: =Inputs!$B$4*8760*Inputs!$B$5*(1-Inputs!$B$6)^(D$4-1) -> 91980 | E6: =Inputs!$B$4*8760*Inputs!$B$5*(1-Inputs!$B$6)^(E$4-1) -> 91520.1 | F6: =Inputs!$B$4*8760*Inputs!$B$5*(1-Inputs!$B$6)^(F$4-1) -> 91062.5 | G6: =Inputs!$B$4*8760*Inputs!$B$5*(1-Inputs!$B$6)^(G$4-1) -> 90607.187 | H6: =Inputs!$B$4*8760*Inputs!$B$5*(1-Inputs!$B$6)^(H$4-1) -> 90154.151 | I6: =Inputs!$B$4*8760*Inputs!$B$5*(1-Inputs!$B$6)^(I$4-1) -> 89703.38 | J6: =Inputs!$B$4*8760*Inputs!$B$5*(1-Inputs!$B$6)^(J$4-1) -> 89254.863 | K6: =Inputs!$B$4*8760*Inputs!$B$5*(1-Inputs!$B$6)^(K$4-1) -> 88808.589 | ... W6: =Inputs!$B$4*8760*Inputs!$B$5*(1-Inputs!$B$6)^(W$4-1) -> 83624.193
A7: Revenue | B7: $m | C7: =SUM(D7:W7) -> 166.70463 | D7: =D6*Inputs!$B$9/10^6 -> 8.7381 | E7: =E6*Inputs!$B$9/10^6 -> 8.6944095 | F7: =F6*Inputs!$B$9/10^6 -> 8.6509375 | G7: =G6*Inputs!$B$9/10^6 -> 8.6076828 | H7: =H6*Inputs!$B$9/10^6 -> 8.5646444 | I7: =I6*Inputs!$B$9/10^6 -> 8.5218211 | J7: =J6*Inputs!$B$9/10^6 -> 8.479212 | K7: =K6*Inputs!$B$9/10^6 -> 8.436816 | ... W7: =W6*Inputs!$B$9/10^6 -> 7.9442983
A8: Opex | B8: $m | C8: =SUM(D8:W8) -> -26.727107 | D8: =-Inputs!$B$11*(1+Inputs!$B$12)^(D$4-1) -> -1.1 | E8: =-Inputs!$B$11*(1+Inputs!$B$12)^(E$4-1) -> -1.122 | F8: =-Inputs!$B$11*(1+Inputs!$B$12)^(F$4-1) -> -1.14444 | G8: =-Inputs!$B$11*(1+Inputs!$B$12)^(G$4-1) -> -1.1673288 | H8: =-Inputs!$B$11*(1+Inputs!$B$12)^(H$4-1) -> -1.1906754 | I8: =-Inputs!$B$11*(1+Inputs!$B$12)^(I$4-1) -> -1.2144889 | J8: =-Inputs!$B$11*(1+Inputs!$B$12)^(J$4-1) -> -1.2387787 | K8: =-Inputs!$B$11*(1+Inputs!$B$12)^(K$4-1) -> -1.2635542 | ... W8: =-Inputs!$B$11*(1+Inputs!$B$12)^(W$4-1) -> -1.6024923
A9: EBITDA | B9: $m | C9: =SUM(D9:W9) -> 139.97753 | D9: =D7+D8 -> 7.6381 | E9: =E7+E8 -> 7.5724095 | F9: =F7+F8 -> 7.5064975 | G9: =G7+G8 -> 7.440354 | H9: =H7+H8 -> 7.373969 | I9: =I7+I8 -> 7.3073322 | J9: =J7+J8 -> 7.2404334 | K9: =K7+K8 -> 7.1732617 | ... W9: =W7+W8 -> 6.341806
A10: Depreciation (tax) | B10: $m | D10: =-'Capital Stack'!$B$9/Inputs!$B$15 -> -2.75 | E10: =-'Capital Stack'!$B$9/Inputs!$B$15 -> -2.75 | F10: =-'Capital Stack'!$B$9/Inputs!$B$15 -> -2.75 | G10: =-'Capital Stack'!$B$9/Inputs!$B$15 -> -2.75 | H10: =-'Capital Stack'!$B$9/Inputs!$B$15 -> -2.75 | I10: =-'Capital Stack'!$B$9/Inputs!$B$15 -> -2.75 | J10: =-'Capital Stack'!$B$9/Inputs!$B$15 -> -2.75 | K10: =-'Capital Stack'!$B$9/Inputs!$B$15 -> -2.75 | ... W10: =-'Capital Stack'!$B$9/Inputs!$B$15 -> -2.75
A11: Tax paid | B11: $m | C11: =SUM(D11:W11) -> -18.358859 | D11: =IF(D$4<=Inputs!$B$14,0,-MAX(0,(D9+D10)*Inputs!$B$13)) -> 0 | E11: =IF(E$4<=Inputs!$B$14,0,-MAX(0,(E9+E10)*Inputs!$B$13)) -> 0 | F11: =IF(F$4<=Inputs!$B$14,0,-MAX(0,(F9+F10)*Inputs!$B$13)) -> 0 | G11: =IF(G$4<=Inputs!$B$14,0,-MAX(0,(G9+G10)*Inputs!$B$13)) -> 0 | H11: =IF(H$4<=Inputs!$B$14,0,-MAX(0,(H9+H10)*Inputs!$B$13)) -> 0 | I11: =IF(I$4<=Inputs!$B$14,0,-MAX(0,(I9+I10)*Inputs!$B$13)) -> -1.3671997 | J11: =IF(J$4<=Inputs!$B$14,0,-MAX(0,(J9+J10)*Inputs!$B$13)) -> -1.34713 | K11: =IF(K$4<=Inputs!$B$14,0,-MAX(0,(K9+K10)*Inputs!$B$13)) -> -1.3269785 | ... W11: =IF(W$4<=Inputs!$B$14,0,-MAX(0,(W9+W10)*Inputs!$B$13)) -> -1.0775418
A12: CFADS — base case | B12: $m | C12: =SUM(D12:W12) -> 121.61867 | D12: =D9+D11 -> 7.6381 | E12: =E9+E11 -> 7.5724095 | F12: =F9+F11 -> 7.5064975 | G12: =G9+G11 -> 7.440354 | H12: =H9+H11 -> 7.373969 | I12: =I9+I11 -> 5.9401326 | J12: =J9+J11 -> 5.8933034 | K12: =K9+K11 -> 5.8462832 | ... W12: =W9+W11 -> 5.2642642
A14: CURRENT SCENARIO (applies the stress levers on the Inputs sheet)
A15: Net generation after haircut | B15: MWh | D15: =D6*(1-Inputs!$B$33) -> 91980 | E15: =E6*(1-Inputs!$B$33) -> 91520.1 | F15: =F6*(1-Inputs!$B$33) -> 91062.5 | G15: =G6*(1-Inputs!$B$33) -> 90607.187 | H15: =H6*(1-Inputs!$B$33) -> 90154.151 | I15: =I6*(1-Inputs!$B$33) -> 89703.38 | J15: =J6*(1-Inputs!$B$33) -> 89254.863 | K15: =K6*(1-Inputs!$B$33) -> 88808.589 | ... W15: =W6*(1-Inputs!$B$33) -> 83624.193
A16: US$ value of tariff after FX (1 − depreciation × (1 − pass-through)) | B16: factor | D16: =1-Inputs!$B$30*(1-Inputs!$B$31) -> 1 | E16: =1-Inputs!$B$30*(1-Inputs!$B$31) -> 1 | F16: =1-Inputs!$B$30*(1-Inputs!$B$31) -> 1 | G16: =1-Inputs!$B$30*(1-Inputs!$B$31) -> 1 | H16: =1-Inputs!$B$30*(1-Inputs!$B$31) -> 1 | I16: =1-Inputs!$B$30*(1-Inputs!$B$31) -> 1 | J16: =1-Inputs!$B$30*(1-Inputs!$B$31) -> 1 | K16: =1-Inputs!$B$30*(1-Inputs!$B$31) -> 1 | ... W16: =1-Inputs!$B$30*(1-Inputs!$B$31) -> 1
A17: Revenue collected | B17: $m | C17: =SUM(D17:W17) -> 166.70463 | D17: =D15*Inputs!$B$9/10^6*D16*Inputs!$B$32 -> 8.7381 | E17: =E15*Inputs!$B$9/10^6*E16*Inputs!$B$32 -> 8.6944095 | F17: =F15*Inputs!$B$9/10^6*F16*Inputs!$B$32 -> 8.6509375 | G17: =G15*Inputs!$B$9/10^6*G16*Inputs!$B$32 -> 8.6076828 | H17: =H15*Inputs!$B$9/10^6*H16*Inputs!$B$32 -> 8.5646444 | I17: =I15*Inputs!$B$9/10^6*I16*Inputs!$B$32 -> 8.5218211 | J17: =J15*Inputs!$B$9/10^6*J16*Inputs!$B$32 -> 8.479212 | K17: =K15*Inputs!$B$9/10^6*K16*Inputs!$B$32 -> 8.436816 | ... W17: =W15*Inputs!$B$9/10^6*W16*Inputs!$B$32 -> 7.9442983
A18: Opex (with overrun) | B18: $m | C18: =SUM(D18:W18) -> -26.727107 | D18: =D8*(1+Inputs!$B$34) -> -1.1 | E18: =E8*(1+Inputs!$B$34) -> -1.122 | F18: =F8*(1+Inputs!$B$34) -> -1.14444 | G18: =G8*(1+Inputs!$B$34) -> -1.1673288 | H18: =H8*(1+Inputs!$B$34) -> -1.1906754 | I18: =I8*(1+Inputs!$B$34) -> -1.2144889 | J18: =J8*(1+Inputs!$B$34) -> -1.2387787 | K18: =K8*(1+Inputs!$B$34) -> -1.2635542 | ... W18: =W8*(1+Inputs!$B$34) -> -1.6024923
A19: EBITDA | B19: $m | C19: =SUM(D19:W19) -> 139.97753 | D19: =D17+D18 -> 7.6381 | E19: =E17+E18 -> 7.5724095 | F19: =F17+F18 -> 7.5064975 | G19: =G17+G18 -> 7.440354 | H19: =H17+H18 -> 7.373969 | I19: =I17+I18 -> 7.3073322 | J19: =J17+J18 -> 7.2404334 | K19: =K17+K18 -> 7.1732617 | ... W19: =W17+W18 -> 6.341806
A20: Tax paid | B20: $m | C20: =SUM(D20:W20) -> -18.358859 | D20: =IF(D$4<=Inputs!$B$14,0,-MAX(0,(D19+D10)*Inputs!$B$13)) -> 0 | E20: =IF(E$4<=Inputs!$B$14,0,-MAX(0,(E19+E10)*Inputs!$B$13)) -> 0 | F20: =IF(F$4<=Inputs!$B$14,0,-MAX(0,(F19+F10)*Inputs!$B$13)) -> 0 | G20: =IF(G$4<=Inputs!$B$14,0,-MAX(0,(G19+G10)*Inputs!$B$13)) -> 0 | H20: =IF(H$4<=Inputs!$B$14,0,-MAX(0,(H19+H10)*Inputs!$B$13)) -> 0 | I20: =IF(I$4<=Inputs!$B$14,0,-MAX(0,(I19+I10)*Inputs!$B$13)) -> -1.3671997 | J20: =IF(J$4<=Inputs!$B$14,0,-MAX(0,(J19+J10)*Inputs!$B$13)) -> -1.34713 | K20: =IF(K$4<=Inputs!$B$14,0,-MAX(0,(K19+K10)*Inputs!$B$13)) -> -1.3269785 | ... W20: =IF(W$4<=Inputs!$B$14,0,-MAX(0,(W19+W10)*Inputs!$B$13)) -> -1.0775418
A21: CFADS — current scenario | B21: $m | C21: =SUM(D21:W21) -> 121.61867 | D21: =D19+D20 -> 7.6381 | E21: =E19+E20 -> 7.5724095 | F21: =F19+F20 -> 7.5064975 | G21: =G19+G20 -> 7.440354 | H21: =H19+H20 -> 7.373969 | I21: =I19+I20 -> 5.9401326 | J21: =J19+J20 -> 5.8933034 | K21: =K19+K20 -> 5.8462832 | ... W21: =W19+W20 -> 5.2642642
A23: DEBT SIZING BY SCULPTING (on base case)
A24: In tenor? (1 = yes) | B24: flag | D24: =IF(D$4<=Inputs!$B$25,1,0) -> 1 | E24: =IF(E$4<=Inputs!$B$25,1,0) -> 1 | F24: =IF(F$4<=Inputs!$B$25,1,0) -> 1 | G24: =IF(G$4<=Inputs!$B$25,1,0) -> 1 | H24: =IF(H$4<=Inputs!$B$25,1,0) -> 1 | I24: =IF(I$4<=Inputs!$B$25,1,0) -> 1 | J24: =IF(J$4<=Inputs!$B$25,1,0) -> 1 | K24: =IF(K$4<=Inputs!$B$25,1,0) -> 1 | ... W24: =IF(W$4<=Inputs!$B$25,1,0) -> 0
A25: Sculpted debt service capacity = CFADS ÷ target DSCR | B25: $m | C25: =SUM(D25:W25) -> 70.222823 | D25: =D12/Inputs!$B$23*D24 -> 5.6578519 | E25: =E12/Inputs!$B$23*E24 -> 5.6091922 | F25: =F12/Inputs!$B$23*F24 -> 5.5603685 | G25: =G12/Inputs!$B$23*G24 -> 5.5113733 | H25: =H12/Inputs!$B$23*H24 -> 5.4621992 | I25: =I12/Inputs!$B$23*I24 -> 4.4000982 | J25: =J12/Inputs!$B$23*J24 -> 4.3654099 | K25: =K12/Inputs!$B$23*K24 -> 4.3305802 | ... W25: =W12/Inputs!$B$23*W24 -> 0
A26: Discount factor at senior rate | B26: factor | D26: =1/(1+Inputs!$B$26)^D$4 -> 0.90909091 | E26: =1/(1+Inputs!$B$26)^E$4 -> 0.82644628 | F26: =1/(1+Inputs!$B$26)^F$4 -> 0.7513148 | G26: =1/(1+Inputs!$B$26)^G$4 -> 0.68301346 | H26: =1/(1+Inputs!$B$26)^H$4 -> 0.62092132 | I26: =1/(1+Inputs!$B$26)^I$4 -> 0.56447393 | J26: =1/(1+Inputs!$B$26)^J$4 -> 0.51315812 | K26: =1/(1+Inputs!$B$26)^K$4 -> 0.46650738 | ... W26: =1/(1+Inputs!$B$26)^W$4 -> 0.14864363
A27: PV of debt service capacity | B27: $m | C27: =SUM(D27:W27) -> 37.402145 | D27: =D25*D26 -> 5.1435017 | E27: =E25*E26 -> 4.6356961 | F27: =F25*F26 -> 4.1775871 | G27: =G25*G26 -> 3.7643421 | H27: =H25*H26 -> 3.391596 | I27: =I25*I26 -> 2.4837407 | J27: =J25*J26 -> 2.2401455 | K27: =K25*K26 -> 2.0202476 | ... W27: =W25*W26 -> 0
A30: Debt capacity at target DSCR (sum of PVs) | C30: =C27 -> 37.402145
A31: Senior debt actually raised (from Capital Stack) | C31: ='Capital Stack'!$B$14 -> 37.402145
A32: Scale factor (raised ÷ capacity) | C32: =IF(C30=0,0,C31/C30) -> 1
A34: SENIOR DEBT SCHEDULE (debt service fixed at financial close)
A35: Opening balance | B35: $m | D35: =$C$31 -> 37.402145 | E35: =D39 -> 35.484507 | F35: =E39 -> 33.423766 | G35: =F39 -> 31.205774 | H35: =G39 -> 28.814978 | I35: =H39 -> 26.234277 | J35: =I39 -> 24.457606 | K35: =J39 -> 22.537957 | L35: =K39 -> 20.461173 | ... W35: =V39 -> -1.4304202e-13
A36: Scheduled debt service (sculpted) | B36: $m | C36: =SUM(D36:W36) -> 70.222823 | D36: =D25*$C$32 -> 5.6578519 | E36: =E25*$C$32 -> 5.6091922 | F36: =F25*$C$32 -> 5.5603685 | G36: =G25*$C$32 -> 5.5113733 | H36: =H25*$C$32 -> 5.4621992 | I36: =I25*$C$32 -> 4.4000982 | J36: =J25*$C$32 -> 4.3654099 | K36: =K25*$C$32 -> 4.3305802 | ... W36: =W25*$C$32 -> 0
A37: Interest | B37: $m | C37: =SUM(D37:W37) -> 32.820678 | D37: =D35*Inputs!$B$26 -> 3.7402145 | E37: =E35*Inputs!$B$26 -> 3.5484507 | F37: =F35*Inputs!$B$26 -> 3.3423766 | G37: =G35*Inputs!$B$26 -> 3.1205774 | H37: =H35*Inputs!$B$26 -> 2.8814978 | I37: =I35*Inputs!$B$26 -> 2.6234277 | J37: =J35*Inputs!$B$26 -> 2.4457606 | K37: =K35*Inputs!$B$26 -> 2.2537957 | ... W37: =W35*Inputs!$B$26 -> -1.4304202e-14
A38: Principal repaid | B38: $m | C38: =SUM(D38:W38) -> 37.402145 | D38: =D36-D37 -> 1.9176374 | E38: =E36-E37 -> 2.0607415 | F38: =F36-F37 -> 2.2179919 | G38: =G36-G37 -> 2.3907959 | H38: =H36-H37 -> 2.5807014 | I38: =I36-I37 -> 1.7766705 | J38: =J36-J37 -> 1.9196493 | K38: =K36-K37 -> 2.0767845 | ... W38: =W36-W37 -> 1.4304202e-14
A39: Closing balance | B39: $m | D39: =D35-D38 -> 35.484507 | E39: =E35-E38 -> 33.423766 | F39: =F35-F38 -> 31.205774 | G39: =G35-G38 -> 28.814978 | H39: =H35-H38 -> 26.234277 | I39: =I35-I38 -> 24.457606 | J39: =J35-J38 -> 22.537957 | K39: =K35-K38 -> 20.461173 | ... W39: =W35-W38 -> -1.5734622e-13
A41: DSCR = CFADS (scenario) ÷ debt service | B41: x | D41: =IF(D36>0,D21/D36,"") -> 1.35 | E41: =IF(E36>0,E21/E36,"") -> 1.35 | F41: =IF(F36>0,F21/F36,"") -> 1.35 | G41: =IF(G36>0,G21/G36,"") -> 1.35 | H41: =IF(H36>0,H21/H36,"") -> 1.35 | I41: =IF(I36>0,I21/I36,"") -> 1.35 | J41: =IF(J36>0,J21/J36,"") -> 1.35 | K41: =IF(K36>0,K21/K36,"") -> 1.35 | ... W41: =IF(W36>0,W21/W36,"")
A42: Cash to equity after senior debt service | B42: $m | C42: =SUM(D42:W42) -> 51.395844 | D42: =D21-D36 -> 1.9802481 | E42: =E21-E36 -> 1.9632173 | F42: =F21-F36 -> 1.946129 | G42: =G21-G36 -> 1.9289807 | H42: =H21-H36 -> 1.9117697 | I42: =I21-I36 -> 1.5400344 | J42: =J21-J36 -> 1.5278935 | K42: =K21-K36 -> 1.5157031 | ... W42: =W21-W36 -> 5.2642642
A43: PV of remaining CFADS over debt life (for LLCR, yr 1 only) | B43: $m | C43: =SUM(D43:W43) -> 50.492896 | D43: =D21*D26*D24 -> 6.9437273 | E43: =E21*E26*E24 -> 6.2581897 | F43: =F21*F26*F24 -> 5.6397426 | G43: =G21*G26*G24 -> 5.0818619 | H43: =H21*H26*H24 -> 4.5786546 | I43: =I21*I26*I24 -> 3.35305 | J43: =J21*J26*J24 -> 3.0241965 | K43: =K21*K26*K24 -> 2.7273343 | ... W43: =W21*W26*W24 -> 0
A45: RESULTS
A47: Minimum DSCR | C47: =MIN(D41:W41) -> 1.35
A48: Average DSCR | C48: =AVERAGE(D41:W41) -> 1.35
A49: LLCR at close = PV(CFADS over tenor) ÷ debt | C49: =IF(C31=0,0,C43/C31) -> 1.35
...

Sheet Exercise Log
A1: Workshop exercise — record each scenario you run
A3: Scenario | B3: Naira depreciation | C3: FX pass-through | D3: Payment rate | E3: Gen. haircut | F3: Opex overrun | G3: Min DSCR | H3: LLCR | I3: Sponsor IRR | J3: Fund / Restructure / Reject? | K3: Mitigant proposed
A4: Example: base case | B4: 0 | C4: 1 | D4: 1 | E4: 0 | F4: 0 | G4: (type result) | J4: Fund | K4: —
A12: Copy the Min DSCR, LLCR and Sponsor IRR from the 'Capital Stack' sheet after changing the yellow levers on 'Inputs'.
