Workbook
Name CHK_TOL: InpC!$F$101
Name SMU: InpC!$F$103
Name LIVE_RESULTS: Track!$H$8:$H$69
Name TRACK_ACTIVE: Track!$H$5
Name TRK_COMMENT: Track!$H$77:$H$78
Name unit: InpC!$F$102

Sheet Cover
B2: TrainStat Project Finance Model: complete
B3: Mastering Infrastructure and Project Finance Boot Camp | Lagos Business School | 14 to 22 October 2026
B4: bongo.ai | MIPF | Prof Bongo Adi | +234 706 164 8699 | badi@lbs.edu.ng | bongo.adi@fulbrightmail.org
B7: MODEL STATUS | C7: =IF(FinStat!F80+FinStat!F83+FinStat!F86+Time!F120+IF(ABS(Constr!F55)>CHK_TOL,1,0)+IF(SUMPRODUCT(ABS(Constr!J48:Q48))>CHK_TOL,1,0)=0,"ALL CHECKS PASSED","CHECK ERRORS: see FinStat and Constr") -> ALL CHECKS PASSED
B8: Active scenario | C8: =InpC!F3 -> Base
B9: Scenario definitions | C9: Base: inflation 7% falling to 3%, fare US$7.15, O&M as contracted. Downside: fare -10% and O&M +10%. Upside: fare +10%.
B10: Debt sizing | C10: =IF(ABS(Sculpt!F32)<1,"Debt drawn equals debt sized","RE-RUN GOAL SEEK: debt drawn less debt sized = "&TEXT(Sculpt!F32,"#,##0")) -> Debt drawn equals debt sized
B11: CONTENTS
B12: Dashboard | C12: Key results, annual summary and charts
B13: InpC | C13: Constants and scenario switch (yellow = typed assumption)
B14: InpS | C14: Time-series inputs: trains, arrivals, occupancy, repayment profiles, extra funding
B15: Time | C15: Timeline, flags and integrity checks
B16: Esc | C16: Inflation and escalation factors
B17: Constr | C17: Construction period: spend, fees, interest during construction, sources and uses, opening balances
B18: OpRev | C18: Demand and operating revenue, cash received, receivables
B19: OpCost | C19: Operating cost, cash paid, payables
B20: Tax | C20: Tax depreciation, tax paid, tax expense, deferred tax
B21: NCA | C21: Capital expenditure, depreciation, asset balance
B22: Debt | C22: Senior debt: repayment profile, interest, balance
B23: Sculpt | C23: Debt capacity, sizing and sculpted repayment
... B30: Track | C30: Scenario log: live results and stored runs
B33: COLOUR CODE
B34: Yellow fill | C34: Typed assumption (input)
B35: Blue font | C35: Link pulled in from another row or sheet
B36: Red font | C36: Key result row used by other sheets
B37: Black font | C37: Intermediate calculation
B40: HOW TO RUN
B41: 1. Choose the scenario in InpC!F3 (drop-down). Everything recalculates.
B42: 2. Change assumptions only in InpC (constants) and InpS (time series).
B43: 3. Confirm the status line above says ALL CHECKS PASSED.
B44: 4. To store a run: copy Track!H8:H69, paste values into M, N or O (Paste Special, Values).
B45: 5. After changing price, cost, tenor or DSCR inputs: Goal Seek Sculpt!F32 to 0 by changing the active scenario's gearing cell on InpC row 72 (J72 Base, K72 Downside, L72 Upside); then set the facility on InpC row 131 to ROUNDUP(Sculpt!F29, 0) for that scenario and repeat both until stable (the facility drives the fees, which drive the project cost).
B47: CHANGE LOG (v1.0, 8 October 2026)
B48: 1. Ghost formulas removed: seven sheets carried about 1,238,318 formulas and formats out to column XFD (the sheet edge), far beyond the 84-column timeline (J to CO). Trimming them cuts the file from about 6.0 MB to 0.4 MB and makes recalculation take seconds instead of many minutes. The unused scratch sheet 'Temp' (about 50,000 formulas) was removed.
B49: 2. Defined names LIVE_RESULTS, TRACK_ACTIVE and TRK_COMMENT repaired (they pointed at deleted cells); name 'unit' re-pointed from an external link to InpC!F102; sheet-level names on Track that pointed at an external workbook removed; Time print area extended to column CO; external link removed.
B50: 3. Typos corrected: Scenario, arrival, Investment, Accounting, available, period, NPV of ...
B51: 4. Stray zeros removed (Tax C28, C35; InpC row 45; InpS J74).
B52: 5. Total and check ranges extended to column CO (they stopped at BY, BV or CQ): the three FinStat checks now cover every column, Time!H79 now counts the post-forecast flag.
... B64: 17. Conventions retained and documented in the Prompt Book: all sponsor funding is dated at COD in Val (equity is actually paid in during construction, so the blended IRR is measured from COD); tax losses are refunded in cash (no loss carry-forward); the model has no DSRA draw and no dividend lock-up.

Sheet Dashboard
B2: TrainStat: dashboard | F2: ="Scenario: "&InpC!F3 -> Scenario: Base | K2: =Cover!C7 -> ALL CHECKS PASSED
B5: Shareholder NPV ($000s) | E5: Shareholder IRR (XIRR) | J5: Minimum DSCR | O5: Total CFADS ($000s)
B6: =Val!F41 -> 28243.56 | E6: =Val!F51 -> 0.43033599 | J6: =Ratios!F13 -> 2.2966072 | O6: =Track!H10 -> 591529.28
B9: Senior debt at close ($000s) | E9: Project cost at COD ($000s) | J9: Gearing at COD | O9: LLCR at COD
B10: =Debt!F11 -> 72154.225 | E10: =Constr!F52 -> 101067.8 | J10: =Constr!F53/Constr!F52 -> 0.71391903 | O10: =Ratios!F22 -> 2.3998574
B14: ANNUAL SUMMARY ($000s)
B15: Financial year | C15: 2022 | D15: 2023 | E15: 2024 | F15: 2025 | G15: 2026 | H15: 2027 | I15: 2028 | J15: 2029 | K15: 2030 | L15: 2031 | M15: 2032 | N15: 2033 | O15: 2034 | P15: 2035 | Q15: 2036 | R15: 2037 | S15: 2038 | T15: 2039 | U15: 2040 | V15: 2041
B16: Operating revenue | C16: =SUMIFS(FinStat!$J$9:$CO$9,FinStat!$J$4:$CO$4,C$15) -> 62837.028 | D16: =SUMIFS(FinStat!$J$9:$CO$9,FinStat!$J$4:$CO$4,D$15) -> 66458.897 | E16: =SUMIFS(FinStat!$J$9:$CO$9,FinStat!$J$4:$CO$4,E$15) -> 70598.708 | F16: =SUMIFS(FinStat!$J$9:$CO$9,FinStat!$J$4:$CO$4,F$15) -> 72981.116 | G16: =SUMIFS(FinStat!$J$9:$CO$9,FinStat!$J$4:$CO$4,G$15) -> 76493.107 | H16: =SUMIFS(FinStat!$J$9:$CO$9,FinStat!$J$4:$CO$4,H$15) -> 80130.149 | I16: =SUMIFS(FinStat!$J$9:$CO$9,FinStat!$J$4:$CO$4,I$15) -> 83218.707 | J16: =SUMIFS(FinStat!$J$9:$CO$9,FinStat!$J$4:$CO$4,J$15) -> 87879.262 | ... V16: =SUMIFS(FinStat!$J$9:$CO$9,FinStat!$J$4:$CO$4,V$15) -> 133493.04
B17: Operating cost | C17: =SUMIFS(FinStat!$J$10:$CO$10,FinStat!$J$4:$CO$4,C$15) -> -40792.852 | D17: =SUMIFS(FinStat!$J$10:$CO$10,FinStat!$J$4:$CO$4,D$15) -> -43322.487 | E17: =SUMIFS(FinStat!$J$10:$CO$10,FinStat!$J$4:$CO$4,E$15) -> -45216.961 | F17: =SUMIFS(FinStat!$J$10:$CO$10,FinStat!$J$4:$CO$4,F$15) -> -46742.444 | G17: =SUMIFS(FinStat!$J$10:$CO$10,FinStat!$J$4:$CO$4,G$15) -> -48144.717 | H17: =SUMIFS(FinStat!$J$10:$CO$10,FinStat!$J$4:$CO$4,H$15) -> -49589.058 | I17: =SUMIFS(FinStat!$J$10:$CO$10,FinStat!$J$4:$CO$4,I$15) -> -51076.73 | J17: =SUMIFS(FinStat!$J$10:$CO$10,FinStat!$J$4:$CO$4,J$15) -> -52609.032 | ... V17: =SUMIFS(FinStat!$J$10:$CO$10,FinStat!$J$4:$CO$4,V$15) -> -76522.488
B18: EBITDA | C18: =SUMIFS(FinStat!$J$11:$CO$11,FinStat!$J$4:$CO$4,C$15) -> 22044.177 | D18: =SUMIFS(FinStat!$J$11:$CO$11,FinStat!$J$4:$CO$4,D$15) -> 23136.41 | E18: =SUMIFS(FinStat!$J$11:$CO$11,FinStat!$J$4:$CO$4,E$15) -> 25381.748 | F18: =SUMIFS(FinStat!$J$11:$CO$11,FinStat!$J$4:$CO$4,F$15) -> 26238.672 | G18: =SUMIFS(FinStat!$J$11:$CO$11,FinStat!$J$4:$CO$4,G$15) -> 28348.39 | H18: =SUMIFS(FinStat!$J$11:$CO$11,FinStat!$J$4:$CO$4,H$15) -> 30541.091 | I18: =SUMIFS(FinStat!$J$11:$CO$11,FinStat!$J$4:$CO$4,I$15) -> 32141.977 | J18: =SUMIFS(FinStat!$J$11:$CO$11,FinStat!$J$4:$CO$4,J$15) -> 35270.229 | ... V18: =SUMIFS(FinStat!$J$11:$CO$11,FinStat!$J$4:$CO$4,V$15) -> 56970.556
B19: CFADS | C19: =SUMIFS(FinStat!$J$39:$CO$39,FinStat!$J$4:$CO$4,C$15) -> 22641.77 | D19: =SUMIFS(FinStat!$J$39:$CO$39,FinStat!$J$4:$CO$4,D$15) -> 20599.828 | E19: =SUMIFS(FinStat!$J$39:$CO$39,FinStat!$J$4:$CO$4,E$15) -> 22274.917 | F19: =SUMIFS(FinStat!$J$39:$CO$39,FinStat!$J$4:$CO$4,F$15) -> 21693.19 | G19: =SUMIFS(FinStat!$J$39:$CO$39,FinStat!$J$4:$CO$4,G$15) -> 22880.839 | H19: =SUMIFS(FinStat!$J$39:$CO$39,FinStat!$J$4:$CO$4,H$15) -> 24514.231 | I19: =SUMIFS(FinStat!$J$39:$CO$39,FinStat!$J$4:$CO$4,I$15) -> 24415.303 | J19: =SUMIFS(FinStat!$J$39:$CO$39,FinStat!$J$4:$CO$4,J$15) -> 26326.737 | ... V19: =SUMIFS(FinStat!$J$39:$CO$39,FinStat!$J$4:$CO$4,V$15) -> 40576.132
B20: Senior debt service | C20: =SUMIFS(FinStat!$J$94:$CO$94,FinStat!$J$4:$CO$4,C$15) -> 9204.8079 | D20: =SUMIFS(FinStat!$J$94:$CO$94,FinStat!$J$4:$CO$4,D$15) -> 8337.4416 | E20: =SUMIFS(FinStat!$J$94:$CO$94,FinStat!$J$4:$CO$4,E$15) -> 9116.7282 | F20: =SUMIFS(FinStat!$J$94:$CO$94,FinStat!$J$4:$CO$4,F$15) -> 8906.0985 | G20: =SUMIFS(FinStat!$J$94:$CO$94,FinStat!$J$4:$CO$4,G$15) -> 9481.041 | H20: =SUMIFS(FinStat!$J$94:$CO$94,FinStat!$J$4:$CO$4,H$15) -> 10264.804 | I20: =SUMIFS(FinStat!$J$94:$CO$94,FinStat!$J$4:$CO$4,I$15) -> 10285.635 | J20: =SUMIFS(FinStat!$J$94:$CO$94,FinStat!$J$4:$CO$4,J$15) -> 11211.035 | ... V20: =SUMIFS(FinStat!$J$94:$CO$94,FinStat!$J$4:$CO$4,V$15) -> 5.9938227e-13
B21: Dividends | C21: =-SUMIFS(FinStat!$J$51:$CO$51,FinStat!$J$4:$CO$4,C$15) -> 6208.8704 | D21: =-SUMIFS(FinStat!$J$51:$CO$51,FinStat!$J$4:$CO$4,D$15) -> 7184.2923 | E21: =-SUMIFS(FinStat!$J$51:$CO$51,FinStat!$J$4:$CO$4,E$15) -> 8658.7429 | F21: =-SUMIFS(FinStat!$J$51:$CO$51,FinStat!$J$4:$CO$4,F$15) -> 9370.148 | G21: =-SUMIFS(FinStat!$J$51:$CO$51,FinStat!$J$4:$CO$4,G$15) -> 10884.216 | H21: =-SUMIFS(FinStat!$J$51:$CO$51,FinStat!$J$4:$CO$4,H$15) -> 12582.612 | I21: =-SUMIFS(FinStat!$J$51:$CO$51,FinStat!$J$4:$CO$4,I$15) -> 13973.428 | J21: =-SUMIFS(FinStat!$J$51:$CO$51,FinStat!$J$4:$CO$4,J$15) -> 16701.545 | ... V21: =-SUMIFS(FinStat!$J$51:$CO$51,FinStat!$J$4:$CO$4,V$15) -> 38068.623
B22: DSCR (CFADS / debt service) | C22: =IF(ABS(C20)>CHK_TOL,C19/C20,0) -> 2.4597765 | D22: =IF(ABS(D20)>CHK_TOL,D19/D20,0) -> 2.4707613 | E22: =IF(ABS(E20)>CHK_TOL,E19/E20,0) -> 2.4433016 | F22: =IF(ABS(F20)>CHK_TOL,F19/F20,0) -> 2.435768 | G22: =IF(ABS(G20)>CHK_TOL,G19/G20,0) -> 2.4133256 | H22: =IF(ABS(H20)>CHK_TOL,H19/H20,0) -> 2.3881832 | I22: =IF(ABS(I20)>CHK_TOL,I19/I20,0) -> 2.3737284 | J22: =IF(ABS(J20)>CHK_TOL,J19/J20,0) -> 2.3482878 | ... V22: =IF(ABS(V20)>CHK_TOL,V19/V20,0) -> 0

Sheet InpC
A1: =RIGHT(CELL("filename", A1), LEN(CELL("filename", A1)) - SEARCH("]", CELL("filename", A1)))
E3: Scenario name | F3: Base | J3: Base | K3: Downside | L3: Upside | N3: Scenario definitions
E4: Scenario switch | F4: =MATCH(F3,I3:M3,0) -> 2 | N4: Base: inflation 7% falling to 3%; fare 7.15; O&M as contracted
F5: Constant | G5: Unit | N5: Downside: Base with fare -10% (6.435) and O&M +10%
N6: Upside: Base with fare +10% (7.865)
A7: TIME
E9: First date of time rulers | F9: {=INDEX(I9:M9,$F$4)} -> 44378 | G9: date | J9: 44378 | K9: 44378 | L9: 44378
E10: Acquisition / initial balance date | F10: {=INDEX(I10:M10,$F$4)} -> 44561 | G10: date | J10: 44561 | K10: 44561 | L10: 44561
E11: Length of forecast period | F11: {=INDEX(I11:M11,$F$4)} -> 20 | G11: years | J11: 20 | K11: 20 | L11: 20
E12: Months per model period | F12: {=INDEX(I12:M12,$F$4)} -> 3 | G12: months | J12: 3 | K12: 3 | L12: 3
A14: ESCALATION
E16: Start of the inflation year | F16: {=INDEX(I16:M16,$F$4)} -> % p.a | J16: % p.a | K16: % p.a | L16: % p.a
E17: 44256 | F17: {=INDEX(I17:M17,$F$4)} -> 0.07 | G17: % p.a | J17: 0.07 | K17: 0.07 | L17: 0.07
E18: 44621 | F18: {=INDEX(I18:M18,$F$4)} -> 0.06 | G18: % p.a | J18: 0.06 | K18: 0.06 | L18: 0.06
E19: 44986 | F19: {=INDEX(I19:M19,$F$4)} -> 0.05 | G19: % p.a | J19: 0.05 | K19: 0.05 | L19: 0.05
E20: 45352 | F20: {=INDEX(I20:M20,$F$4)} -> 0.04 | G20: % p.a | J20: 0.04 | K20: 0.04 | L20: 0.04
E21: 45717 | F21: {=INDEX(I21:M21,$F$4)} -> 0.03 | G21: % p.a | J21: 0.03 | K21: 0.03 | L21: 0.03
E23: CPI index at acquisition date | F23: {=INDEX(I23:M23,$F$4)} -> 145 | G23: index | J23: 145 | K23: 145 | L23: 145
E25: CPI index at handling signature date | F25: {=INDEX(I25:M25,$F$4)} -> 120 | G25: index | J25: 120 | K25: 120 | L25: 120
E27: CPI index at O&M signature date | F27: {=INDEX(I27:M27,$F$4)} -> 132 | G27: index | J27: 132 | K27: 132 | L27: 132
A29: OPERATING REVENUE
E31: Train capacity - domestic | F31: {=INDEX(I31:M31,$F$4)} -> 350 | G31: seats | J31: 350 | K31: 350 | L31: 350
E33: Train capacity - international | F33: {=INDEX(I33:M33,$F$4)} -> 150 | G33: seats | J33: 150 | K33: 150 | L33: 150
E35: Average fare per passenger | F35: {=INDEX(I35:M35,$F$4)} -> 7.15 | G35: USD/pax | J35: 7.15 | K35: 6.435 | L35: 7.865
E37: Account receivables days | F37: {=INDEX(I37:M37,$F$4)} -> 25 | G37: days | J37: 25 | K37: 25 | L37: 25
A40: OPERATING COST
E42: Handling cost- fixed per annum | F42: {=INDEX(I42:M42,$F$4)} -> 4500 | G42: $ 000s | J42: 4500 | K42: 4500 | L42: 4500
E44: Handling cost - variable | F44: {=INDEX(I44:M44,$F$4)} -> 550 | G44: USD/arrival | J44: 550 | K44: 550 | L44: 550
E46: O&M cost - sensitivity | F46: {=INDEX(I46:M46,$F$4)} -> 0 | G46: (1 + X%) | J46: 0 | K46: 0.1 | L46: 0
E48: O&M cost- fixed per annum | F48: {=INDEX(I48:M48,$F$4)} -> 3300 | G48: =SMU -> $ 000s | J48: 3300 | K48: 3300 | L48: 3300
E50: Account payables days | F50: {=INDEX(I50:M50,$F$4)} -> 35 | G50: days | J50: 35 | K50: 35 | L50: 35
A53: NON CURRENT ASSET
E55: Investment / addition date | F55: {=INDEX(I55:M55,$F$4)} -> $000s | J55: $000s | K55: $000s | L55: $000s
E56: 45291 | F56: {=INDEX(I56:M56,$F$4)} -> 2000 | G56: $ 000s | J56: 2000 | K56: 2000 | L56: 2000
E57: 45657 | F57: {=INDEX(I57:M57,$F$4)} -> 1000 | G57: $ 000s | J57: 1000 | K57: 1000 | L57: 1000
E58: 46022 | F58: {=INDEX(I58:M58,$F$4)} -> 1500 | G58: $ 000s | J58: 1500 | K58: 1500 | L58: 1500
E59: 46387 | F59: {=INDEX(I59:M59,$F$4)} -> 1000 | G59: $ 000s | J59: 1000 | K59: 1000 | L59: 1000
E60: 46752 | F60: {=INDEX(I60:M60,$F$4)} -> 500 | G60: $ 000s | J60: 500 | K60: 500 | L60: 500
E61: 47118 | F61: {=INDEX(I61:M61,$F$4)} -> 1000 | G61: $ 000s | J61: 1000 | K61: 1000 | L61: 1000
E62: 47483 | F62: {=INDEX(I62:M62,$F$4)} -> 1000 | G62: $ 000s | J62: 1000 | K62: 1000 | L62: 1000
...

Sheet InpS
A1: =RIGHT(CELL("filename", A1), LEN(CELL("filename", A1)) - SEARCH("]", CELL("filename", A1)))
E2: Model period ending | J2: 44469 | K2: 44561 | L2: 44651 | M2: 44742 | N2: 44834 | O2: 44926 | P2: 45016 | Q2: 45107 | R2: 45199 | S2: 45291 | T2: 45382 | U2: 45473 | V2: 45565 | W2: 45657 | X2: 45747 | Y2: 45838 | Z2: 45930 | AA2: 46022 | AB2: 46112 | AC2: 46203 | AD2: 46295 | AE2: 46387 | AF2: 46477 | AG2: 46568 | AH2: 46660 | AI2: 46752 | AJ2: 46843 | AK2: 46934 | AL2: 47026 | AM2: 47118 | AN2: 47208 | AO2: 47299 | AP2: 47391 | AQ2: 47483 | AR2: 47573 | AS2: 47664 | AT2: 47756 | AU2: 47848 | AV2: 47938 | AW2: 48029 | AX2: 48121 | AY2: 48213 | AZ2: 48304 | BA2: 48395 | BB2: 48487 | BC2: 48579 | BD2: 48669 | BE2: 48760 | BF2: 48852 | BG2: 48944 | BH2: 49034 | BI2: 49125 | BJ2: 49217 | BK2: 49309 | BL2: 49399 | BM2: 49490 | BN2: 49582 | BO2: 49674 | BP2: 49765 | BQ2: 49856 | BR2: 49948 | BS2: 50040 | BT2: 50130 | BU2: 50221 | BV2: 50313 | BW2: 50405 | BX2: 50495 | BY2: 50586 | BZ2: 50678 | CA2: 50770 | CB2: 50860 | CC2: 50951 | CD2: 51043 | CE2: 51135 | CF2: 51226 | CG2: 51317 | CH2: 51409 | CI2: 51501 | CJ2: 51591 | CK2: 51682 | CL2: 51774 | CM2: 51866 | CN2: 51956 | CO2: 52047
E3: Timeline label | J3: Pre-fcst | K3: Fin close | L3: Forecast | M3: Forecast | N3: Forecast | O3: Forecast | P3: Forecast | Q3: Forecast | R3: Forecast | S3: Forecast | T3: Forecast | U3: Forecast | V3: Forecast | W3: Forecast | X3: Forecast | Y3: Forecast | Z3: Forecast | AA3: Forecast | AB3: Forecast | AC3: Forecast | AD3: Forecast | AE3: Forecast | AF3: Forecast | AG3: Forecast | AH3: Forecast | AI3: Forecast | AJ3: Forecast | AK3: Forecast | AL3: Forecast | AM3: Forecast | AN3: Forecast | AO3: Forecast | AP3: Forecast | AQ3: Forecast | AR3: Forecast | AS3: Forecast | AT3: Forecast | AU3: Forecast | AV3: Forecast | AW3: Forecast | AX3: Forecast | AY3: Forecast | AZ3: Forecast | BA3: Forecast | BB3: Forecast | BC3: Forecast | BD3: Forecast | BE3: Forecast | BF3: Forecast | BG3: Forecast | BH3: Forecast | BI3: Forecast | BJ3: Forecast | BK3: Forecast | BL3: Forecast | BM3: Forecast | BN3: Forecast | BO3: Forecast | BP3: Forecast | BQ3: Forecast | BR3: Forecast | BS3: Forecast | BT3: Forecast | BU3: Forecast | BV3: Forecast | BW3: Forecast | BX3: Forecast | BY3: Forecast | BZ3: Forecast | CA3: Forecast | CB3: Forecast | CC3: Forecast | CD3: Forecast | CE3: Forecast | CF3: Forecast | CG3: Forecast | CH3: Forecast | CI3: Forecast | CJ3: Forecast | CK3: Forecast | CL3: Forecast | CM3: Forecast | CN3: Post-fcst | CO3: Post-fcst
E4: Financial year ending | J4: 2021 | K4: 2021 | L4: 2022 | M4: 2022 | N4: 2022 | O4: 2022 | P4: 2023 | Q4: 2023 | R4: 2023 | S4: 2023 | T4: 2024 | U4: 2024 | V4: 2024 | W4: 2024 | X4: 2025 | Y4: 2025 | Z4: 2025 | AA4: 2025 | AB4: 2026 | AC4: 2026 | AD4: 2026 | AE4: 2026 | AF4: 2027 | AG4: 2027 | AH4: 2027 | AI4: 2027 | AJ4: 2028 | AK4: 2028 | AL4: 2028 | AM4: 2028 | AN4: 2029 | AO4: 2029 | AP4: 2029 | AQ4: 2029 | AR4: 2030 | AS4: 2030 | AT4: 2030 | AU4: 2030 | AV4: 2031 | AW4: 2031 | AX4: 2031 | AY4: 2031 | AZ4: 2032 | BA4: 2032 | BB4: 2032 | BC4: 2032 | BD4: 2033 | BE4: 2033 | BF4: 2033 | BG4: 2033 | BH4: 2034 | BI4: 2034 | BJ4: 2034 | BK4: 2034 | BL4: 2035 | BM4: 2035 | BN4: 2035 | BO4: 2035 | BP4: 2036 | BQ4: 2036 | BR4: 2036 | BS4: 2036 | BT4: 2037 | BU4: 2037 | BV4: 2037 | BW4: 2037 | BX4: 2038 | BY4: 2038 | BZ4: 2038 | CA4: 2038 | CB4: 2039 | CC4: 2039 | CD4: 2039 | CE4: 2039 | CF4: 2040 | CG4: 2040 | CH4: 2040 | CI4: 2040 | CJ4: 2041 | CK4: 2041 | CL4: 2041 | CM4: 2041 | CN4: 2042 | CO4: 2042
E5: Model column counter | F5: Constant | G5: Unit | H5: Total | J5: 1 | K5: 2 | L5: 3 | M5: 4 | N5: 5 | O5: 6 | P5: 7 | Q5: 8 | R5: 9 | S5: 10 | T5: 11 | U5: 12 | V5: 13 | W5: 14 | X5: 15 | Y5: 16 | Z5: 17 | AA5: 18 | AB5: 19 | AC5: 20 | AD5: 21 | AE5: 22 | AF5: 23 | AG5: 24 | AH5: 25 | AI5: 26 | AJ5: 27 | AK5: 28 | AL5: 29 | AM5: 30 | AN5: 31 | AO5: 32 | AP5: 33 | AQ5: 34 | AR5: 35 | AS5: 36 | AT5: 37 | AU5: 38 | AV5: 39 | AW5: 40 | AX5: 41 | AY5: 42 | AZ5: 43 | BA5: 44 | BB5: 45 | BC5: 46 | BD5: 47 | BE5: 48 | BF5: 49 | BG5: 50 | BH5: 51 | BI5: 52 | BJ5: 53 | BK5: 54 | BL5: 55 | BM5: 56 | BN5: 57 | BO5: 58 | BP5: 59 | BQ5: 60 | BR5: 61 | BS5: 62 | BT5: 63 | BU5: 64 | BV5: 65 | BW5: 66 | BX5: 67 | BY5: 68 | BZ5: 69 | CA5: 70 | CB5: 71 | CC5: 72 | CD5: 73 | CE5: 74 | CF5: 75 | CG5: 76 | CH5: 77 | CI5: 78 | CJ5: 79 | CK5: 80 | CL5: 81 | CM5: 82 | CN5: 83 | CO5: 84
A7: OPERATING REVENUE
E8: Trains - domestic | G8: trains | H8: =SUM(J8:CO8) -> 2520 | J8: 30 | K8: 30 | L8: 30 | M8: 30 | N8: 30 | O8: 30 | P8: 30 | Q8: 30 | R8: 30 | S8: 30 | T8: 30 | U8: 30 | V8: 30 | W8: 30 | X8: 30 | Y8: 30 | Z8: 30 | AA8: 30 | AB8: 30 | AC8: 30 | AD8: 30 | AE8: 30 | AF8: 30 | AG8: 30 | AH8: 30 | AI8: 30 | AJ8: 30 | AK8: 30 | AL8: 30 | AM8: 30 | AN8: 30 | AO8: 30 | AP8: 30 | AQ8: 30 | AR8: 30 | AS8: 30 | AT8: 30 | AU8: 30 | AV8: 30 | AW8: 30 | AX8: 30 | AY8: 30 | AZ8: 30 | BA8: 30 | BB8: 30 | BC8: 30 | BD8: 30 | BE8: 30 | BF8: 30 | BG8: 30 | BH8: 30 | BI8: 30 | BJ8: 30 | BK8: 30 | BL8: 30 | BM8: 30 | BN8: 30 | BO8: 30 | BP8: 30 | BQ8: 30 | BR8: 30 | BS8: 30 | BT8: 30 | BU8: 30 | BV8: 30 | BW8: 30 | BX8: 30 | BY8: 30 | BZ8: 30 | CA8: 30 | CB8: 30 | CC8: 30 | CD8: 30 | CE8: 30 | CF8: 30 | CG8: 30 | CH8: 30 | CI8: 30 | CJ8: 30 | CK8: 30 | CL8: 30 | CM8: 30 | CN8: 30 | CO8: 30
E9: Trains - international | G9: trains | H9: =SUM(J9:CO9) -> 1326 | J9: 10 | K9: 12 | L9: 12 | M9: 14 | N9: 14 | O9: 16 | P9: 16 | Q9: 16 | R9: 16 | S9: 16 | T9: 16 | U9: 16 | V9: 16 | W9: 16 | X9: 16 | Y9: 16 | Z9: 16 | AA9: 16 | AB9: 16 | AC9: 16 | AD9: 16 | AE9: 16 | AF9: 16 | AG9: 16 | AH9: 16 | AI9: 16 | AJ9: 16 | AK9: 16 | AL9: 16 | AM9: 16 | AN9: 16 | AO9: 16 | AP9: 16 | AQ9: 16 | AR9: 16 | AS9: 16 | AT9: 16 | AU9: 16 | AV9: 16 | AW9: 16 | AX9: 16 | AY9: 16 | AZ9: 16 | BA9: 16 | BB9: 16 | BC9: 16 | BD9: 16 | BE9: 16 | BF9: 16 | BG9: 16 | BH9: 16 | BI9: 16 | BJ9: 16 | BK9: 16 | BL9: 16 | BM9: 16 | BN9: 16 | BO9: 16 | BP9: 16 | BQ9: 16 | BR9: 16 | BS9: 16 | BT9: 16 | BU9: 16 | BV9: 16 | BW9: 16 | BX9: 16 | BY9: 16 | BZ9: 16 | CA9: 16 | CB9: 16 | CC9: 16 | CD9: 16 | CE9: 16 | CF9: 16 | CG9: 16 | CH9: 16 | CI9: 16 | CJ9: 16 | CK9: 16 | CL9: 16 | CM9: 16 | CN9: 16 | CO9: 16
E11: Arrivals per train - domestic | G11: arrivals / train | J11: 370 | K11: 350 | L11: 370 | M11: 350 | N11: 370 | O11: 350 | P11: 370 | Q11: 350 | R11: 370 | S11: 350 | T11: 370 | U11: 350 | V11: 370 | W11: 350 | X11: 370 | Y11: 350 | Z11: 370 | AA11: 350 | AB11: 370 | AC11: 350 | AD11: 370 | AE11: 350 | AF11: 370 | AG11: 350 | AH11: 370 | AI11: 350 | AJ11: 370 | AK11: 350 | AL11: 370 | AM11: 350 | AN11: 370 | AO11: 350 | AP11: 370 | AQ11: 350 | AR11: 370 | AS11: 350 | AT11: 370 | AU11: 350 | AV11: 370 | AW11: 350 | AX11: 370 | AY11: 350 | AZ11: 370 | BA11: 350 | BB11: 370 | BC11: 350 | BD11: 370 | BE11: 350 | BF11: 370 | BG11: 350 | BH11: 350 | BI11: 370 | BJ11: 350 | BK11: 370 | BL11: 350 | BM11: 370 | BN11: 350 | BO11: 370 | BP11: 350 | BQ11: 350 | BR11: 370 | BS11: 350 | BT11: 370 | BU11: 350 | BV11: 370 | BW11: 370 | BX11: 370 | BY11: 370 | BZ11: 370 | CA11: 370 | CB11: 370 | CC11: 370 | CD11: 370 | CE11: 370 | CF11: 370 | CG11: 370 | CH11: 370 | CI11: 370 | CJ11: 370 | CK11: 370 | CL11: 370 | CM11: 370 | CN11: 370 | CO11: 370
E12: Arrivals per train - international | G12: arrivals / train | J12: 34 | K12: 34 | L12: 34 | M12: 44 | N12: 44 | O12: 44 | P12: 44 | Q12: 44 | R12: 44 | S12: 44 | T12: 44 | U12: 44 | V12: 44 | W12: 44 | X12: 44 | Y12: 44 | Z12: 44 | AA12: 44 | AB12: 44 | AC12: 44 | AD12: 44 | AE12: 44 | AF12: 44 | AG12: 44 | AH12: 44 | AI12: 44 | AJ12: 44 | AK12: 44 | AL12: 44 | AM12: 44 | AN12: 44 | AO12: 44 | AP12: 44 | AQ12: 44 | AR12: 44 | AS12: 44 | AT12: 44 | AU12: 44 | AV12: 44 | AW12: 44 | AX12: 44 | AY12: 44 | AZ12: 44 | BA12: 44 | BB12: 44 | BC12: 44 | BD12: 44 | BE12: 44 | BF12: 44 | BG12: 44 | BH12: 44 | BI12: 44 | BJ12: 44 | BK12: 44 | BL12: 44 | BM12: 44 | BN12: 44 | BO12: 44 | BP12: 44 | BQ12: 44 | BR12: 44 | BS12: 44 | BT12: 44 | BU12: 44 | BV12: 44 | BW12: 44 | BX12: 44 | BY12: 44 | BZ12: 44 | CA12: 44 | CB12: 44 | CC12: 44 | CD12: 44 | CE12: 44 | CF12: 44 | CG12: 44 | CH12: 44 | CI12: 44 | CJ12: 44 | CK12: 44 | CL12: 44 | CM12: 44 | CN12: 44 | CO12: 44
E14: Occupancy - domestic | G14: % | J14: 0.55 | K14: 0.55 | L14: 0.55 | M14: 0.55 | N14: 0.55 | O14: 0.55 | P14: 0.55 | Q14: 0.55 | R14: 0.55 | S14: 0.55 | T14: 0.56 | U14: 0.56 | V14: 0.56 | W14: 0.56 | X14: 0.56 | Y14: 0.56 | Z14: 0.56 | AA14: 0.56 | AB14: 0.56 | AC14: 0.56 | AD14: 0.58 | AE14: 0.58 | AF14: 0.58 | AG14: 0.58 | AH14: 0.58 | AI14: 0.58 | AJ14: 0.58 | AK14: 0.58 | AL14: 0.58 | AM14: 0.6 | AN14: 0.6 | AO14: 0.6 | AP14: 0.6 | AQ14: 0.6 | AR14: 0.6 | AS14: 0.6 | AT14: 0.6 | AU14: 0.6 | AV14: 0.6 | AW14: 0.6 | AX14: 0.62 | AY14: 0.62 | AZ14: 0.62 | BA14: 0.62 | BB14: 0.62 | BC14: 0.62 | BD14: 0.62 | BE14: 0.62 | BF14: 0.62 | BG14: 0.62 | BH14: 0.62 | BI14: 0.62 | BJ14: 0.62 | BK14: 0.62 | BL14: 0.62 | BM14: 0.62 | BN14: 0.62 | BO14: 0.62 | BP14: 0.62 | BQ14: 0.62 | BR14: 0.62 | BS14: 0.62 | BT14: 0.62 | BU14: 0.62 | BV14: 0.62 | BW14: 0.62 | BX14: 0.62 | BY14: 0.62 | BZ14: 0.62 | CA14: 0.62 | CB14: 0.62 | CC14: 0.62 | CD14: 0.62 | CE14: 0.62 | CF14: 0.62 | CG14: 0.62 | CH14: 0.62 | CI14: 0.62 | CJ14: 0.62 | CK14: 0.62 | CL14: 0.62 | CM14: 0.62 | CN14: 0.62 | CO14: 0.62
E15: Occupancy - international | G15: % | J15: 0.45 | K15: 0.45 | L15: 0.45 | M15: 0.45 | N15: 0.45 | O15: 0.45 | P15: 0.45 | Q15: 0.45 | R15: 0.45 | S15: 0.45 | T15: 0.45 | U15: 0.45 | V15: 0.45 | W15: 0.45 | X15: 0.45 | Y15: 0.45 | Z15: 0.45 | AA15: 0.45 | AB15: 0.45 | AC15: 0.45 | AD15: 0.45 | AE15: 0.45 | AF15: 0.45 | AG15: 0.45 | AH15: 0.45 | AI15: 0.45 | AJ15: 0.45 | AK15: 0.45 | AL15: 0.45 | AM15: 0.45 | AN15: 0.45 | AO15: 0.45 | AP15: 0.45 | AQ15: 0.45 | AR15: 0.45 | AS15: 0.45 | AT15: 0.45 | AU15: 0.45 | AV15: 0.45 | AW15: 0.45 | AX15: 0.55 | AY15: 0.55 | AZ15: 0.55 | BA15: 0.55 | BB15: 0.55 | BC15: 0.55 | BD15: 0.55 | BE15: 0.55 | BF15: 0.55 | BG15: 0.55 | BH15: 0.55 | BI15: 0.55 | BJ15: 0.55 | BK15: 0.55 | BL15: 0.55 | BM15: 0.55 | BN15: 0.55 | BO15: 0.55 | BP15: 0.55 | BQ15: 0.55 | BR15: 0.55 | BS15: 0.55 | BT15: 0.55 | BU15: 0.55 | BV15: 0.55 | BW15: 0.55 | BX15: 0.55 | BY15: 0.55 | BZ15: 0.55 | CA15: 0.55 | CB15: 0.55 | CC15: 0.55 | CD15: 0.55 | CE15: 0.55 | CF15: 0.55 | CG15: 0.55 | CH15: 0.55 | CI15: 0.55 | CJ15: 0.55 | CK15: 0.55 | CL15: 0.55 | CM15: 0.55 | CN15: 0.55 | CO15: 0.55
A17: SENIOR DEBT
E18: Senior debt profile 1 - 7.5 years | G18: % | H18: =SUM(J18:CO18) -> 1 | O18: 0.033333333 | P18: 0.033333333 | Q18: 0.033333333 | R18: 0.033333333 | S18: 0.033333333 | T18: 0.033333333 | U18: 0.033333333 | V18: 0.033333333 | W18: 0.033333333 | X18: 0.033333333 | Y18: 0.033333333 | Z18: 0.033333333 | AA18: 0.033333333 | AB18: 0.033333333 | AC18: 0.033333333 | AD18: 0.033333333 | AE18: 0.033333333 | AF18: 0.033333333 | AG18: 0.033333333 | AH18: 0.033333333 | AI18: 0.033333333 | AJ18: 0.033333333 | AK18: 0.033333333 | AL18: 0.033333333 | AM18: 0.033333333 | AN18: 0.033333333 | AO18: 0.033333333 | AP18: 0.033333333 | AQ18: 0.033333333 | AR18: 0.033333333
E19: Senior debt profile 2 - 10 years | G19: % | H19: =SUM(J19:CO19) -> 1 | O19: 0.025 | P19: 0.025 | Q19: 0.025 | R19: 0.025 | S19: 0.025 | T19: 0.025 | U19: 0.025 | V19: 0.025 | W19: 0.025 | X19: 0.025 | Y19: 0.025 | Z19: 0.025 | AA19: 0.025 | AB19: 0.025 | AC19: 0.025 | AD19: 0.025 | AE19: 0.025 | AF19: 0.025 | AG19: 0.025 | AH19: 0.025 | AI19: 0.025 | AJ19: 0.025 | AK19: 0.025 | AL19: 0.025 | AM19: 0.025 | AN19: 0.025 | AO19: 0.025 | AP19: 0.025 | AQ19: 0.025 | AR19: 0.025 | AS19: 0.025 | AT19: 0.025 | AU19: 0.025 | AV19: 0.025 | AW19: 0.025 | AX19: 0.025 | AY19: 0.025 | AZ19: 0.025 | BA19: 0.025 | BB19: 0.025
E20: Senior debt profile 3 - 15 years | G20: % | H20: =SUM(J20:CO20) -> 1 | O20: 0.016666667 | P20: 0.016666667 | Q20: 0.016666667 | R20: 0.016666667 | S20: 0.016666667 | T20: 0.016666667 | U20: 0.016666667 | V20: 0.016666667 | W20: 0.016666667 | X20: 0.016666667 | Y20: 0.016666667 | Z20: 0.016666667 | AA20: 0.016666667 | AB20: 0.016666667 | AC20: 0.016666667 | AD20: 0.016666667 | AE20: 0.016666667 | AF20: 0.016666667 | AG20: 0.016666667 | AH20: 0.016666667 | AI20: 0.016666667 | AJ20: 0.016666667 | AK20: 0.016666667 | AL20: 0.016666667 | AM20: 0.016666667 | AN20: 0.016666667 | AO20: 0.016666667 | AP20: 0.016666667 | AQ20: 0.016666667 | AR20: 0.016666667 | AS20: 0.016666667 | AT20: 0.016666667 | AU20: 0.016666667 | AV20: 0.016666667 | AW20: 0.016666667 | AX20: 0.016666667 | AY20: 0.016666667 | AZ20: 0.016666667 | BA20: 0.016666667 | BB20: 0.016666667 | BC20: 0.016666667 | BD20: 0.016666667 | BE20: 0.016666667 | BF20: 0.016666667 | BG20: 0.016666667 | BH20: 0.016666667 | BI20: 0.016666667 | BJ20: 0.016666667 | BK20: 0.016666667 | BL20: 0.016666667 | BM20: 0.016666667 | BN20: 0.016666667 | BO20: 0.016666667 | BP20: 0.016666667 | BQ20: 0.016666667 | BR20: 0.016666667 | BS20: 0.016666667 | BT20: 0.016666667 | BU20: 0.016666667 | BV20: 0.016666667
A21: ADDITIONAL FUNDING (after financial close)
E22: Senior debt - additional drawdown | G22: $ 000s | H22: =SUM(J22:CO22) -> 0 | J22: 0 | K22: 0 | L22: 0 | M22: 0 | N22: 0 | O22: 0 | P22: 0 | Q22: 0 | R22: 0 | S22: 0 | T22: 0 | U22: 0 | V22: 0 | W22: 0 | X22: 0 | Y22: 0 | Z22: 0 | AA22: 0 | AB22: 0 | AC22: 0 | AD22: 0 | AE22: 0 | AF22: 0 | AG22: 0 | AH22: 0 | AI22: 0 | AJ22: 0 | AK22: 0 | AL22: 0 | AM22: 0 | AN22: 0 | AO22: 0 | AP22: 0 | AQ22: 0 | AR22: 0 | AS22: 0 | AT22: 0 | AU22: 0 | AV22: 0 | AW22: 0 | AX22: 0 | AY22: 0 | AZ22: 0 | BA22: 0 | BB22: 0 | BC22: 0 | BD22: 0 | BE22: 0 | BF22: 0 | BG22: 0 | BH22: 0 | BI22: 0 | BJ22: 0 | BK22: 0 | BL22: 0 | BM22: 0 | BN22: 0 | BO22: 0 | BP22: 0 | BQ22: 0 | BR22: 0 | BS22: 0 | BT22: 0 | BU22: 0 | BV22: 0 | BW22: 0 | BX22: 0 | BY22: 0 | BZ22: 0 | CA22: 0 | CB22: 0 | CC22: 0 | CD22: 0 | CE22: 0 | CF22: 0 | CG22: 0 | CH22: 0 | CI22: 0 | CJ22: 0 | CK22: 0 | CL22: 0 | CM22: 0 | CN22: 0 | CO22: 0
E23: Share capital - additional injection | G23: $ 000s | H23: =SUM(J23:CO23) -> 0 | J23: 0 | K23: 0 | L23: 0 | M23: 0 | N23: 0 | O23: 0 | P23: 0 | Q23: 0 | R23: 0 | S23: 0 | T23: 0 | U23: 0 | V23: 0 | W23: 0 | X23: 0 | Y23: 0 | Z23: 0 | AA23: 0 | AB23: 0 | AC23: 0 | AD23: 0 | AE23: 0 | AF23: 0 | AG23: 0 | AH23: 0 | AI23: 0 | AJ23: 0 | AK23: 0 | AL23: 0 | AM23: 0 | AN23: 0 | AO23: 0 | AP23: 0 | AQ23: 0 | AR23: 0 | AS23: 0 | AT23: 0 | AU23: 0 | AV23: 0 | AW23: 0 | AX23: 0 | AY23: 0 | AZ23: 0 | BA23: 0 | BB23: 0 | BC23: 0 | BD23: 0 | BE23: 0 | BF23: 0 | BG23: 0 | BH23: 0 | BI23: 0 | BJ23: 0 | BK23: 0 | BL23: 0 | BM23: 0 | BN23: 0 | BO23: 0 | BP23: 0 | BQ23: 0 | BR23: 0 | BS23: 0 | BT23: 0 | BU23: 0 | BV23: 0 | BW23: 0 | BX23: 0 | BY23: 0 | BZ23: 0 | CA23: 0 | CB23: 0 | CC23: 0 | CD23: 0 | CE23: 0 | CF23: 0 | CG23: 0 | CH23: 0 | CI23: 0 | CJ23: 0 | CK23: 0 | CL23: 0 | CM23: 0 | CN23: 0 | CO23: 0

Sheet Time
A1: =RIGHT(CELL("filename", A1), LEN(CELL("filename", A1)) - SEARCH("]", CELL("filename", A1)))
E2: =Time!E$25 -> Model period ending | J2: =Time!J$25 -> 44469 | K2: =Time!K$25 -> 44561 | L2: =Time!L$25 -> 44651 | M2: =Time!M$25 -> 44742 | N2: =Time!N$25 -> 44834 | O2: =Time!O$25 -> 44926 | P2: =Time!P$25 -> 45016 | Q2: =Time!Q$25 -> 45107 | ... CO2: =Time!CO$25 -> 52047
E3: =Time!E$111 -> Timeline label | J3: =Time!J$111 -> Pre-fcst | K3: =Time!K$111 -> Fin close | L3: =Time!L$111 -> Forecast | M3: =Time!M$111 -> Forecast | N3: =Time!N$111 -> Forecast | O3: =Time!O$111 -> Forecast | P3: =Time!P$111 -> Forecast | Q3: =Time!Q$111 -> Forecast | ... CO3: =Time!CO$111 -> Post-fcst
E4: =Time!E$37 -> Financial year ending | J4: =Time!J$37 -> 2021 | K4: =Time!K$37 -> 2021 | L4: =Time!L$37 -> 2022 | M4: =Time!M$37 -> 2022 | N4: =Time!N$37 -> 2022 | O4: =Time!O$37 -> 2022 | P4: =Time!P$37 -> 2023 | Q4: =Time!Q$37 -> 2023 | ... CO4: =Time!CO$37 -> 2042
E5: =Time!E$10 -> Model column counter | F5: Constant | G5: Unit | H5: Total | J5: =Time!J$10 -> 1 | K5: =Time!K$10 -> 2 | L5: =Time!L$10 -> 3 | M5: =Time!M$10 -> 4 | N5: =Time!N$10 -> 5 | O5: =Time!O$10 -> 6 | P5: =Time!P$10 -> 7 | Q5: =Time!Q$10 -> 8 | ... CO5: =Time!CO$10 -> 84
A7: TIME RULER
B9: First model column flag
E10: Model column counter | G10: counter | J10: =I10 + 1 -> 1 | K10: =J10 + 1 -> 2 | L10: =K10 + 1 -> 3 | M10: =L10 + 1 -> 4 | N10: =M10 + 1 -> 5 | O10: =N10 + 1 -> 6 | P10: =O10 + 1 -> 7 | Q10: =P10 + 1 -> 8 | ... CO10: =CN10 + 1 -> 84
E11: Model column total | F11: =MAX(J10:CO10) -> 84 | G11: columns
E13: =E$10 -> Model column counter | F13: =F$10 -> 0 | G13: =G$10 -> counter | H13: =H$10 -> 0 | I13: =I$10 -> 0 | J13: =J$10 -> 1 | K13: =K$10 -> 2 | L13: =L$10 -> 3 | ... CO13: =CO$10 -> 84
E14: First model column flag | G14: flag | H14: =SUM(J14:CO14) -> 1 | J14: =IF(J13 = 1, 1, 0) -> 1 | K14: =IF(K13 = 1, 1, 0) -> 0 | L14: =IF(L13 = 1, 1, 0) -> 0 | M14: =IF(M13 = 1, 1, 0) -> 0 | N14: =IF(N13 = 1, 1, 0) -> 0 | O14: =IF(O13 = 1, 1, 0) -> 0 | P14: =IF(P13 = 1, 1, 0) -> 0 | Q14: =IF(Q13 = 1, 1, 0) -> 0 | ... CO14: =IF(CO13 = 1, 1, 0) -> 0
B16: Model period beginning
E17: =InpC!E$9 -> First date of time rulers | F17: =InpC!F$9 -> 44378 | G17: =InpC!G$9 -> date
E18: =InpC!E$12 -> Months per model period | F18: =InpC!F$12 -> 3 | G18: =InpC!G$12 -> months
E19: =E$14 -> First model column flag | F19: =F$14 -> 0 | G19: =G$14 -> flag | H19: =H$14 -> 1 | I19: =I$14 -> 0 | J19: =J$14 -> 1 | K19: =K$14 -> 0 | L19: =L$14 -> 0 | ... CO19: =CO$14 -> 0
E20: Model period beginning | G20: date | J20: =IF(J19 = 1, $F17, DATE(YEAR(I20), MONTH(I20) + $F18, DAY(1))) -> 44378 | K20: =IF(K19 = 1, $F17, DATE(YEAR(J20), MONTH(J20) + $F18, DAY(1))) -> 44470 | L20: =IF(L19 = 1, $F17, DATE(YEAR(K20), MONTH(K20) + $F18, DAY(1))) -> 44562 | M20: =IF(M19 = 1, $F17, DATE(YEAR(L20), MONTH(L20) + $F18, DAY(1))) -> 44652 | N20: =IF(N19 = 1, $F17, DATE(YEAR(M20), MONTH(M20) + $F18, DAY(1))) -> 44743 | O20: =IF(O19 = 1, $F17, DATE(YEAR(N20), MONTH(N20) + $F18, DAY(1))) -> 44835 | P20: =IF(P19 = 1, $F17, DATE(YEAR(O20), MONTH(O20) + $F18, DAY(1))) -> 44927 | Q20: =IF(Q19 = 1, $F17, DATE(YEAR(P20), MONTH(P20) + $F18, DAY(1))) -> 45017 | ... CO20: =IF(CO19 = 1, $F17, DATE(YEAR(CN20), MONTH(CN20) + $F18, DAY(1))) -> 51957
B22: Model period ending
E23: =InpC!E$12 -> Months per model period | F23: =InpC!F$12 -> 3 | G23: =InpC!G$12 -> months
E24: =E$20 -> Model period beginning | F24: =F$20 -> 0 | G24: =G$20 -> date | H24: =H$20 -> 0 | I24: =I$20 -> 0 | J24: =J$20 -> 44378 | K24: =K$20 -> 44470 | L24: =L$20 -> 44562 | ... CO24: =CO$20 -> 51957
E25: Model period ending | G25: date | J25: =DATE(YEAR(J24), MONTH(J24) + $F23, DAY(J24) -1) -> 44469 | K25: =DATE(YEAR(K24), MONTH(K24) + $F23, DAY(K24) -1) -> 44561 | L25: =DATE(YEAR(L24), MONTH(L24) + $F23, DAY(L24) -1) -> 44651 | M25: =DATE(YEAR(M24), MONTH(M24) + $F23, DAY(M24) -1) -> 44742 | N25: =DATE(YEAR(N24), MONTH(N24) + $F23, DAY(N24) -1) -> 44834 | O25: =DATE(YEAR(O24), MONTH(O24) + $F23, DAY(O24) -1) -> 44926 | P25: =DATE(YEAR(P24), MONTH(P24) + $F23, DAY(P24) -1) -> 45016 | Q25: =DATE(YEAR(Q24), MONTH(Q24) + $F23, DAY(Q24) -1) -> 45107 | ... CO25: =DATE(YEAR(CO24), MONTH(CO24) + $F23, DAY(CO24) -1) -> 52047
B27: Days in model period
E28: =E$25 -> Model period ending | F28: =F$25 -> 0 | G28: =G$25 -> date | H28: =H$25 -> 0 | I28: =I$25 -> 0 | J28: =J$25 -> 44469 | K28: =K$25 -> 44561 | L28: =L$25 -> 44651 | ... CO28: =CO$25 -> 52047
D29: less | E29: =E$20 -> Model period beginning | F29: =F$20 -> 0 | G29: =G$20 -> date | H29: =H$20 -> 0 | I29: =I$20 -> 0 | J29: =J$20 -> 44378 | K29: =K$20 -> 44470 | L29: =L$20 -> 44562 | ... CO29: =CO$20 -> 51957
E30: Days in model period | G30: days | J30: =J28-J29+1 -> 92 | K30: =K28-K29+1 -> 92 | L30: =L28-L29+1 -> 90 | M30: =M28-M29+1 -> 91 | N30: =N28-N29+1 -> 92 | O30: =O28-O29+1 -> 92 | P30: =P28-P29+1 -> 90 | Q30: =Q28-Q29+1 -> 91 | ... CO30: =CO28-CO29+1 -> 91
B32: Financial year ending
E33: =InpC!E$100 -> First modelling column financial year number | F33: =InpC!F$100 -> 2021 | G33: =InpC!G$100 -> year #
E34: =InpC!E$98 -> Financial year end month number | F34: =InpC!F$98 -> 12 | G34: =InpC!G$98 -> month #
E35: =E$25 -> Model period ending | F35: =F$25 -> 0 | G35: =G$25 -> date | H35: =H$25 -> 0 | I35: =I$25 -> 0 | J35: =J$25 -> 44469 | K35: =K$25 -> 44561 | L35: =L$25 -> 44651 | ... CO35: =CO$25 -> 52047
E36: =E$14 -> First model column flag | F36: =F$14 -> 0 | G36: =G$14 -> flag | H36: =H$14 -> 1 | I36: =I$14 -> 0 | J36: =J$14 -> 1 | K36: =K$14 -> 0 | L36: =L$14 -> 0 | ... CO36: =CO$14 -> 0
E37: Financial year ending | G37: year # | J37: =IF(J36 = 1, $F33, IF(J35 > (DATE(I37, $F34 + 1, 1) - 1), I37 + 1, I37)) -> 2021 | K37: =IF(K36 = 1, $F33, IF(K35 > (DATE(J37, $F34 + 1, 1) - 1), J37 + 1, J37)) -> 2021 | L37: =IF(L36 = 1, $F33, IF(L35 > (DATE(K37, $F34 + 1, 1) - 1), K37 + 1, K37)) -> 2022 | M37: =IF(M36 = 1, $F33, IF(M35 > (DATE(L37, $F34 + 1, 1) - 1), L37 + 1, L37)) -> 2022 | N37: =IF(N36 = 1, $F33, IF(N35 > (DATE(M37, $F34 + 1, 1) - 1), M37 + 1, M37)) -> 2022 | O37: =IF(O36 = 1, $F33, IF(O35 > (DATE(N37, $F34 + 1, 1) - 1), N37 + 1, N37)) -> 2022 | P37: =IF(P36 = 1, $F33, IF(P35 > (DATE(O37, $F34 + 1, 1) - 1), O37 + 1, O37)) -> 2023 | Q37: =IF(Q36 = 1, $F33, IF(Q35 > (DATE(P37, $F34 + 1, 1) - 1), P37 + 1, P37)) -> 2023 | ... CO37: =IF(CO36 = 1, $F33, IF(CO35 > (DATE(CN37, $F34 + 1, 1) - 1), CN37 + 1, CN37)) -> 2042
A40: FLAGS
B42: Acquisition / initial balance date flag
E43: =InpC!E$10 -> Acquisition / initial balance date | F43: =InpC!F$10 -> 44561 | G43: =InpC!G$10 -> date
E44: =E$25 -> Model period ending | F44: =F$25 -> 0 | G44: =G$25 -> date | H44: =H$25 -> 0 | I44: =I$25 -> 0 | J44: =J$25 -> 44469 | K44: =K$25 -> 44561 | L44: =L$25 -> 44651 | ... CO44: =CO$25 -> 52047
E45: Acquisition / initial balance date flag | G45: flag | H45: =SUM(J45:CO45) -> 1 | J45: =IF(J44 = $F43, 1, 0) -> 0 | K45: =IF(K44 = $F43, 1, 0) -> 1 | L45: =IF(L44 = $F43, 1, 0) -> 0 | M45: =IF(M44 = $F43, 1, 0) -> 0 | N45: =IF(N44 = $F43, 1, 0) -> 0 | O45: =IF(O44 = $F43, 1, 0) -> 0 | P45: =IF(P44 = $F43, 1, 0) -> 0 | Q45: =IF(Q44 = $F43, 1, 0) -> 0 | ... CO45: =IF(CO44 = $F43, 1, 0) -> 0
B47: First forecast period flag
E48: =InpC!E$10 -> Acquisition / initial balance date | F48: =InpC!F$10 -> 44561 | G48: =InpC!G$10 -> date
E49: First forecast period start date | F49: =F48 + 1 -> 44562 | G49: date
E51: =E$49 -> First forecast period start date | F51: =F$49 -> 44562 | G51: =G$49 -> date
E52: =E$25 -> Model period ending | F52: =F$25 -> 0 | G52: =G$25 -> date | H52: =H$25 -> 0 | I52: =I$25 -> 0 | J52: =J$25 -> 44469 | K52: =K$25 -> 44561 | L52: =L$25 -> 44651 | ... CO52: =CO$25 -> 52047
...

Sheet Esc
A1: =RIGHT(CELL("filename", A1), LEN(CELL("filename", A1)) - SEARCH("]", CELL("filename", A1)))
E2: =Time!E$25 -> Model period ending | J2: =Time!J$25 -> 44469 | K2: =Time!K$25 -> 44561 | L2: =Time!L$25 -> 44651 | M2: =Time!M$25 -> 44742 | N2: =Time!N$25 -> 44834 | O2: =Time!O$25 -> 44926 | P2: =Time!P$25 -> 45016 | Q2: =Time!Q$25 -> 45107 | ... CO2: =Time!CO$25 -> 52047
E3: =Time!E$111 -> Timeline label | J3: =Time!J$111 -> Pre-fcst | K3: =Time!K$111 -> Fin close | L3: =Time!L$111 -> Forecast | M3: =Time!M$111 -> Forecast | N3: =Time!N$111 -> Forecast | O3: =Time!O$111 -> Forecast | P3: =Time!P$111 -> Forecast | Q3: =Time!Q$111 -> Forecast | ... CO3: =Time!CO$111 -> Post-fcst
E4: =Time!E$37 -> Financial year ending | J4: =Time!J$37 -> 2021 | K4: =Time!K$37 -> 2021 | L4: =Time!L$37 -> 2022 | M4: =Time!M$37 -> 2022 | N4: =Time!N$37 -> 2022 | O4: =Time!O$37 -> 2022 | P4: =Time!P$37 -> 2023 | Q4: =Time!Q$37 -> 2023 | ... CO4: =Time!CO$37 -> 2042
E5: =Time!E$10 -> Model column counter | F5: Constant | G5: Unit | H5: Total | J5: =Time!J$10 -> 1 | K5: =Time!K$10 -> 2 | L5: =Time!L$10 -> 3 | M5: =Time!M$10 -> 4 | N5: =Time!N$10 -> 5 | O5: =Time!O$10 -> 6 | P5: =Time!P$10 -> 7 | Q5: =Time!Q$10 -> 8 | ... CO5: =Time!CO$10 -> 84
A7: ESCALATION
C9: CPI inflation rate
E10: =InpC!E$16 -> Start of the inflation year | F10: =InpC!F$16 -> % p.a | G10: =InpC!G$16 -> 0
E11: =InpC!E$17 -> 44256 | F11: =InpC!F$17 -> 0.07 | G11: =InpC!G$17 -> % p.a
E12: =InpC!E$18 -> 44621 | F12: =InpC!F$18 -> 0.06 | G12: =InpC!G$18 -> % p.a
E13: =InpC!E$19 -> 44986 | F13: =InpC!F$19 -> 0.05 | G13: =InpC!G$19 -> % p.a
E14: =InpC!E$20 -> 45352 | F14: =InpC!F$20 -> 0.04 | G14: =InpC!G$20 -> % p.a
E15: =InpC!E$21 -> 45717 | F15: =InpC!F$21 -> 0.03 | G15: =InpC!G$21 -> % p.a
E16: =Time!E$25 -> Model period ending | F16: =Time!F$25 -> 0 | G16: =Time!G$25 -> date | H16: =Time!H$25 -> 0 | I16: =Time!I$25 -> 0 | J16: =Time!J$25 -> 44469 | K16: =Time!K$25 -> 44561 | L16: =Time!L$25 -> 44651 | ... CO16: =Time!CO$25 -> 52047
E17: CPI inflation rate p.a | G17: % pa. | J17: =VLOOKUP(J16, $E11:$F15,2,TRUE) -> 0.07 | K17: =VLOOKUP(K16, $E11:$F15,2,TRUE) -> 0.07 | L17: =VLOOKUP(L16, $E11:$F15,2,TRUE) -> 0.06 | M17: =VLOOKUP(M16, $E11:$F15,2,TRUE) -> 0.06 | N17: =VLOOKUP(N16, $E11:$F15,2,TRUE) -> 0.06 | O17: =VLOOKUP(O16, $E11:$F15,2,TRUE) -> 0.06 | P17: =VLOOKUP(P16, $E11:$F15,2,TRUE) -> 0.05 | Q17: =VLOOKUP(Q16, $E11:$F15,2,TRUE) -> 0.05 | ... CO17: =VLOOKUP(CO16, $E11:$F15,2,TRUE) -> 0.03
E19: =InpC!E$99 -> No of periods in a year | F19: =InpC!F$99 -> 4 | G19: =InpC!G$99 -> periods
E20: =E$17 -> CPI inflation rate p.a | F20: =F$17 -> 0 | G20: =G$17 -> % pa. | H20: =H$17 -> 0 | I20: =I$17 -> 0 | J20: =J$17 -> 0.07 | K20: =K$17 -> 0.07 | L20: =L$17 -> 0.06 | ... CO20: =CO$17 -> 0.03
E21: Periodic CPI inflation rate | G21: %pq | J21: =(1 + J20) ^ (1 / $F19) -1 -> 0.017058525 | K21: =(1 + K20) ^ (1 / $F19) -1 -> 0.017058525 | L21: =(1 + L20) ^ (1 / $F19) -1 -> 0.014673846 | M21: =(1 + M20) ^ (1 / $F19) -1 -> 0.014673846 | N21: =(1 + N20) ^ (1 / $F19) -1 -> 0.014673846 | O21: =(1 + O20) ^ (1 / $F19) -1 -> 0.014673846 | P21: =(1 + P20) ^ (1 / $F19) -1 -> 0.012272234 | Q21: =(1 + Q20) ^ (1 / $F19) -1 -> 0.012272234 | ... CO21: =(1 + CO20) ^ (1 / $F19) -1 -> 0.0074170718
B23: CPI escalation factor
E24: =E$21 -> Periodic CPI inflation rate | F24: =F$21 -> 0 | G24: =G$21 -> %pq | H24: =H$21 -> 0 | I24: =I$21 -> 0 | J24: =J$21 -> 0.017058525 | K24: =K$21 -> 0.017058525 | L24: =L$21 -> 0.014673846 | ... CO24: =CO$21 -> 0.0074170718
E25: =Time!E$45 -> Acquisition / initial balance date flag | F25: =Time!F$45 -> 0 | G25: =Time!G$45 -> flag | H25: =Time!H$45 -> 1 | I25: =Time!I$45 -> 0 | J25: =Time!J$45 -> 0 | K25: =Time!K$45 -> 1 | L25: =Time!L$45 -> 0 | ... CO25: =Time!CO$45 -> 0
E26: CPI escalation factor | G26: factor | J26: =IF(J25 = 1, 1, I26 * ( 1 + J24)) -> 0 | K26: =IF(K25 = 1, 1, J26 * ( 1 + K24)) -> 1 | L26: =IF(L25 = 1, 1, K26 * ( 1 + L24)) -> 1.0146738 | M26: =IF(M25 = 1, 1, L26 * ( 1 + M24)) -> 1.029563 | N26: =IF(N25 = 1, 1, M26 * ( 1 + N24)) -> 1.0446707 | O26: =IF(O25 = 1, 1, N26 * ( 1 + O24)) -> 1.06 | P26: =IF(P25 = 1, 1, O26 * ( 1 + P24)) -> 1.0730086 | Q26: =IF(Q25 = 1, 1, P26 * ( 1 + Q24)) -> 1.0861768 | ... CO26: =IF(CO25 = 1, 1, CN26 * ( 1 + CO24)) -> 1.9416902
B28: Handling escalation factor
E29: =InpC!E$23 -> CPI index at acquisition date | F29: =InpC!F$23 -> 145 | G29: =InpC!G$23 -> index
E30: =InpC!E$25 -> CPI index at handling signature date | F30: =InpC!F$25 -> 120 | G30: =InpC!G$25 -> index
E31: =E$26 -> CPI escalation factor | F31: =F$26 -> 0 | G31: =G$26 -> factor | H31: =H$26 -> 0 | I31: =I$26 -> 0 | J31: =J$26 -> 0 | K31: =K$26 -> 1 | L31: =L$26 -> 1.0146738 | ... CO31: =CO$26 -> 1.9416902
E32: Handling escalation factor | G32: factor | J32: =$F29 / $F30 * J31 -> 0 | K32: =$F29 / $F30 * K31 -> 1.2083333 | L32: =$F29 / $F30 * L31 -> 1.2260642 | M32: =$F29 / $F30 * M31 -> 1.2440553 | N32: =$F29 / $F30 * N31 -> 1.2623104 | O32: =$F29 / $F30 * O31 -> 1.2808333 | P32: =$F29 / $F30 * P31 -> 1.296552 | Q32: =$F29 / $F30 * Q31 -> 1.3124636 | ... CO32: =$F29 / $F30 * CO31 -> 2.346209
B34: O&M escalation factor
E35: =InpC!E$23 -> CPI index at acquisition date | F35: =InpC!F$23 -> 145 | G35: =InpC!G$23 -> index
E36: =InpC!E$27 -> CPI index at O&M signature date | F36: =InpC!F$27 -> 132 | G36: =InpC!G$27 -> index
E37: =E$26 -> CPI escalation factor | F37: =F$26 -> 0 | G37: =G$26 -> factor | H37: =H$26 -> 0 | I37: =I$26 -> 0 | J37: =J$26 -> 0 | K37: =K$26 -> 1 | L37: =L$26 -> 1.0146738 | ... CO37: =CO$26 -> 1.9416902
E38: O&M escalation factor | G38: factor | J38: =$F35 / $F36 * J37 -> 0 | K38: =$F35 / $F36 * K37 -> 1.0984848 | L38: =$F35 / $F36 * L37 -> 1.1146038 | M38: =$F35 / $F36 * M37 -> 1.1309594 | N38: =$F35 / $F36 * N37 -> 1.1475549 | O38: =$F35 / $F36 * O37 -> 1.1643939 | P38: =$F35 / $F36 * P37 -> 1.1786837 | Q38: =$F35 / $F36 * Q37 -> 1.1931487 | ... CO38: =$F35 / $F36 * CO37 -> 2.1329173

Sheet Constr
A1: =RIGHT(CELL("filename", A1), LEN(CELL("filename", A1)) - SEARCH("]", CELL("filename", A1)))
E2: Construction period ending | J2: =J13 -> 43921 | K2: =K13 -> 44012 | L2: =L13 -> 44104 | M2: =M13 -> 44196 | N2: =N13 -> 44286 | O2: =O13 -> 44377 | P2: =P13 -> 44469 | Q2: =Q13 -> 44561
E3: Phase | J3: Construction | K3: Construction | L3: Construction | M3: Construction | N3: Construction | O3: Construction | P3: Construction | Q3: Construction
E4: Financial year | J4: =YEAR(J13) -> 2020 | K4: =YEAR(K13) -> 2020 | L4: =YEAR(L13) -> 2020 | M4: =YEAR(M13) -> 2020 | N4: =YEAR(N13) -> 2021 | O4: =YEAR(O13) -> 2021 | P4: =YEAR(P13) -> 2021 | Q4: =YEAR(Q13) -> 2021
E5: Construction quarter counter | F5: Constant | G5: Unit | H5: Total | J5: 1 | K5: =J5+1 -> 2 | L5: =K5+1 -> 3 | M5: =L5+1 -> 4 | N5: =M5+1 -> 5 | O5: =N5+1 -> 6 | P5: =O5+1 -> 7 | Q5: =P5+1 -> 8
A7: CONSTRUCTION TIMELINE
E9: =InpC!E$10 -> Acquisition / initial balance date | F9: =InpC!F$10 -> 44561 | G9: =InpC!G$10 -> date
E10: =InpC!E$12 -> Months per model period | F10: =InpC!F$12 -> 3 | G10: =InpC!G$12 -> months
E11: =InpC!E$113 -> Construction period | F11: =InpC!F$113 -> 8 | G11: =InpC!G$113 -> quarters
E13: Construction period ending | G13: date | J13: =EOMONTH($F$9,-$F$10*($F$11-J$5)) -> 43921 | K13: =EOMONTH($F$9,-$F$10*($F$11-K$5)) -> 44012 | L13: =EOMONTH($F$9,-$F$10*($F$11-L$5)) -> 44104 | M13: =EOMONTH($F$9,-$F$10*($F$11-M$5)) -> 44196 | N13: =EOMONTH($F$9,-$F$10*($F$11-N$5)) -> 44286 | O13: =EOMONTH($F$9,-$F$10*($F$11-O$5)) -> 44377 | P13: =EOMONTH($F$9,-$F$10*($F$11-P$5)) -> 44469 | Q13: =EOMONTH($F$9,-$F$10*($F$11-Q$5)) -> 44561
E14: Days in construction period | G14: days | H14: =SUM(J14:Q14) -> 731 | J14: =J13-EOMONTH(J13,-$F$10) -> 91 | K14: =K13-EOMONTH(K13,-$F$10) -> 91 | L14: =L13-EOMONTH(L13,-$F$10) -> 92 | M14: =M13-EOMONTH(M13,-$F$10) -> 92 | N14: =N13-EOMONTH(N13,-$F$10) -> 90 | O14: =O13-EOMONTH(O13,-$F$10) -> 91 | P14: =P13-EOMONTH(P13,-$F$10) -> 92 | Q14: =Q13-EOMONTH(Q13,-$F$10) -> 92
A16: CONSTRUCTION COST
E17: =InpC!E$115 -> Total construction cost (hard cost) | F17: =InpC!F$115 -> 94850 | G17: =InpC!G$115 -> $ 000s
E18: Spend profile | G18: % | H18: =SUM(J18:Q18) -> 1 | J18: =INDEX(InpC!$F$118:$F$125,J$5) -> 0.05 | K18: =INDEX(InpC!$F$118:$F$125,K$5) -> 0.1 | L18: =INDEX(InpC!$F$118:$F$125,L$5) -> 0.15 | M18: =INDEX(InpC!$F$118:$F$125,M$5) -> 0.2 | N18: =INDEX(InpC!$F$118:$F$125,N$5) -> 0.2 | O18: =INDEX(InpC!$F$118:$F$125,O$5) -> 0.15 | P18: =INDEX(InpC!$F$118:$F$125,P$5) -> 0.1 | Q18: =INDEX(InpC!$F$118:$F$125,Q$5) -> 0.05
E19: Construction cost spend | G19: $ 000s | H19: =SUM(J19:Q19) -> 94850 | J19: =$F$17*J18 -> 4742.5 | K19: =$F$17*K18 -> 9485 | L19: =$F$17*L18 -> 14227.5 | M19: =$F$17*M18 -> 18970 | N19: =$F$17*N18 -> 18970 | O19: =$F$17*O18 -> 14227.5 | P19: =$F$17*P18 -> 9485 | Q19: =$F$17*Q18 -> 4742.5
A21: FEES
E22: =InpC!E$127 -> Upfront fee (% of facility) | F22: =InpC!F$127 -> 0.02 | G22: =InpC!G$127 -> %
E23: =InpC!E$131 -> Senior debt facility (commitment) | F23: =InpC!F$131 -> 72155 | G23: =InpC!G$131 -> $ 000s
E24: =InpC!E$129 -> Commitment fee (% p.a. on undrawn facility) | F24: =InpC!F$129 -> 0.0075 | G24: =InpC!G$129 -> % p.a
E25: Upfront fee | G25: $ 000s | H25: =SUM(J25:Q25) -> 1443.1 | J25: =IF(J$5=1,$F$22*$F$23,0) -> 1443.1 | K25: =IF(K$5=1,$F$22*$F$23,0) -> 0 | L25: =IF(L$5=1,$F$22*$F$23,0) -> 0 | M25: =IF(M$5=1,$F$22*$F$23,0) -> 0 | N25: =IF(N$5=1,$F$22*$F$23,0) -> 0 | O25: =IF(O$5=1,$F$22*$F$23,0) -> 0 | P25: =IF(P$5=1,$F$22*$F$23,0) -> 0 | Q25: =IF(Q$5=1,$F$22*$F$23,0) -> 0
A27: INTEREST AND COMMITMENT FEE DURING CONSTRUCTION
E28: =InpC!E$77 -> All in annual senior debt interest rate | F28: =InpC!F$77 -> 0.065 | G28: =InpC!G$77 -> %
E29: =InpC!E$79 -> Day count convention | F29: =InpC!F$79 -> 360 | G29: =InpC!G$79 -> days
E30: Senior debt balance BEG | G30: $ 000s | J30: =I49 -> 0 | K30: =J49 -> 4513.6773 | L30: =K49 -> 11429.696 | M30: =L49 -> 21805.616 | N30: =M49 -> 35676.148 | O30: =N49 -> 49681.908 | P30: =O49 -> 60452.381 | Q30: =P49 -> 67956.82
E31: Interest during construction (IDC) | G31: $ 000s | H31: =SUM(J31:Q31) -> 4155.2959 | J31: =J30*$F$28/$F$29*J14 -> 0 | K31: =K30*$F$28/$F$29*K14 -> 74.162225 | L31: =L30*$F$28/$F$29*L14 -> 189.85994 | M31: =M30*$F$28/$F$29*M14 -> 362.21552 | N31: =N30*$F$28/$F$29*N14 -> 579.73741 | O31: =O30*$F$28/$F$29*O14 -> 816.30135 | P31: =P30*$F$28/$F$29*P14 -> 1004.1812 | Q31: =Q30*$F$28/$F$29*Q14 -> 1128.8383
E32: Commitment fee | G32: $ 000s | H32: =SUM(J32:Q32) -> 619.4033 | J32: =($F$23-J30)*$F$24/$F$29*J14 -> 136.79385 | K32: =($F$23-K30)*$F$24/$F$29*K14 -> 128.23667 | L32: =($F$23-L30)*$F$24/$F$29*L14 -> 116.39017 | M32: =($F$23-M30)*$F$24/$F$29*M14 -> 96.502985 | N32: =($F$23-N30)*$F$24/$F$29*N14 -> 68.397847 | O32: =($F$23-O30)*$F$24/$F$29*O14 -> 42.605237 | P32: =($F$23-P30)*$F$24/$F$29*P14 -> 22.43002 | Q32: =($F$23-Q30)*$F$24/$F$29*Q14 -> 8.0465115
A34: USES OF FUNDS
E35: =E$19 -> Construction cost spend | G35: $ 000s | H35: =SUM(J35:Q35) -> 94850 | J35: =J19 -> 4742.5 | K35: =K19 -> 9485 | L35: =L19 -> 14227.5 | M35: =M19 -> 18970 | N35: =N19 -> 18970 | O35: =O19 -> 14227.5 | P35: =P19 -> 9485 | Q35: =Q19 -> 4742.5
E36: =E$25 -> Upfront fee | G36: $ 000s | H36: =SUM(J36:Q36) -> 1443.1 | J36: =J25 -> 1443.1 | K36: =K25 -> 0 | L36: =L25 -> 0 | M36: =M25 -> 0 | N36: =N25 -> 0 | O36: =O25 -> 0 | P36: =P25 -> 0 | Q36: =Q25 -> 0
E37: =E$31 -> Interest during construction (IDC) | G37: $ 000s | H37: =SUM(J37:Q37) -> 4155.2959 | J37: =J31 -> 0 | K37: =K31 -> 74.162225 | L37: =L31 -> 189.85994 | M37: =M31 -> 362.21552 | N37: =N31 -> 579.73741 | O37: =O31 -> 816.30135 | P37: =P31 -> 1004.1812 | Q37: =Q31 -> 1128.8383
E38: =E$32 -> Commitment fee | G38: $ 000s | H38: =SUM(J38:Q38) -> 619.4033 | J38: =J32 -> 136.79385 | K38: =K32 -> 128.23667 | L38: =L32 -> 116.39017 | M38: =M32 -> 96.502985 | N38: =N32 -> 68.397847 | O38: =O32 -> 42.605237 | P38: =P32 -> 22.43002 | Q38: =Q32 -> 8.0465115
E39: Total uses of funds | G39: $ 000s | H39: =SUM(J39:Q39) -> 101067.8 | J39: =SUM(J35:J38) -> 6322.3939 | K39: =SUM(K35:K38) -> 9687.3989 | L39: =SUM(L35:L38) -> 14533.75 | M39: =SUM(M35:M38) -> 19428.719 | N39: =SUM(N35:N38) -> 19618.135 | O39: =SUM(O35:O38) -> 15086.407 | P39: =SUM(P35:P38) -> 10511.611 | Q39: =SUM(Q35:Q38) -> 5879.3848
A41: SOURCES OF FUNDS
E42: =InpC!E$72 -> % of NCA financed with debt | F42: =InpC!F$72 -> 0.71391903 | G42: =InpC!G$72 -> %
E43: =InpC!E$133 -> Drawdown method (1 pro-rata, 2 equity first) | F43: =InpC!F$133 -> 1 | G43: =InpC!G$133 -> switch
E44: =InpC!E$135 -> Equity commitment (used by method 2) | F44: =InpC!F$135 -> 40000 | G44: =InpC!G$135 -> $ 000s
E45: Equity drawdown | G45: $ 000s | H45: =SUM(J45:Q45) -> 28913.574 | J45: =IF($F$43=1,J39*(1-$F$42),MIN(J39,$F$44-SUM($I45:I45))) -> 1808.7166 | K45: =IF($F$43=1,K39*(1-$F$42),MIN(K39,$F$44-SUM($I45:J45))) -> 2771.3805 | L45: =IF($F$43=1,L39*(1-$F$42),MIN(L39,$F$44-SUM($I45:K45))) -> 4157.8294 | M45: =IF($F$43=1,M39*(1-$F$42),MIN(M39,$F$44-SUM($I45:L45))) -> 5558.1867 | N45: =IF($F$43=1,N39*(1-$F$42),MIN(N39,$F$44-SUM($I45:M45))) -> 5612.3752 | O45: =IF($F$43=1,O39*(1-$F$42),MIN(O39,$F$44-SUM($I45:N45))) -> 4315.9339 | P45: =IF($F$43=1,P39*(1-$F$42),MIN(P39,$F$44-SUM($I45:O45))) -> 3007.172 | Q45: =IF($F$43=1,Q39*(1-$F$42),MIN(Q39,$F$44-SUM($I45:P45))) -> 1681.9801
E46: Senior debt drawdown | G46: $ 000s | H46: =SUM(J46:Q46) -> 72154.225 | J46: =J39-J45 -> 4513.6773 | K46: =K39-K45 -> 6916.0184 | L46: =L39-L45 -> 10375.921 | M46: =M39-M45 -> 13870.532 | N46: =N39-N45 -> 14005.76 | O46: =O39-O45 -> 10770.473 | P46: =P39-P45 -> 7504.4393 | Q46: =Q39-Q45 -> 4197.4047
E47: Total sources of funds | G47: $ 000s | H47: =SUM(J47:Q47) -> 101067.8 | J47: =J45+J46 -> 6322.3939 | K47: =K45+K46 -> 9687.3989 | L47: =L45+L46 -> 14533.75 | M47: =M45+M46 -> 19428.719 | N47: =N45+N46 -> 19618.135 | O47: =O45+O46 -> 15086.407 | P47: =P45+P46 -> 10511.611 | Q47: =Q45+Q46 -> 5879.3848
E48: Sources less uses (check) | G48: check | H48: =SUM(J48:Q48) -> 0 | J48: =J47-J39 -> 0 | K48: =K47-K39 -> 0 | L48: =L47-L39 -> 0 | M48: =M47-M39 -> 0 | N48: =N47-N39 -> 0 | O48: =O47-O39 -> 0 | P48: =P47-P39 -> 0 | Q48: =Q47-Q39 -> 0
...

Sheet OpRev
A1: =RIGHT(CELL("filename", A1), LEN(CELL("filename", A1)) - SEARCH("]", CELL("filename", A1)))
E2: =Time!E$25 -> Model period ending | J2: =Time!J$25 -> 44469 | K2: =Time!K$25 -> 44561 | L2: =Time!L$25 -> 44651 | M2: =Time!M$25 -> 44742 | N2: =Time!N$25 -> 44834 | O2: =Time!O$25 -> 44926 | P2: =Time!P$25 -> 45016 | Q2: =Time!Q$25 -> 45107 | ... CO2: =Time!CO$25 -> 52047
E3: =Time!E$111 -> Timeline label | J3: =Time!J$111 -> Pre-fcst | K3: =Time!K$111 -> Fin close | L3: =Time!L$111 -> Forecast | M3: =Time!M$111 -> Forecast | N3: =Time!N$111 -> Forecast | O3: =Time!O$111 -> Forecast | P3: =Time!P$111 -> Forecast | Q3: =Time!Q$111 -> Forecast | ... CO3: =Time!CO$111 -> Post-fcst
E4: =Time!E$37 -> Financial year ending | J4: =Time!J$37 -> 2021 | K4: =Time!K$37 -> 2021 | L4: =Time!L$37 -> 2022 | M4: =Time!M$37 -> 2022 | N4: =Time!N$37 -> 2022 | O4: =Time!O$37 -> 2022 | P4: =Time!P$37 -> 2023 | Q4: =Time!Q$37 -> 2023 | ... CO4: =Time!CO$37 -> 2042
E5: =Time!E$10 -> Model column counter | F5: Constant | G5: Unit | H5: Total | J5: =Time!J$10 -> 1 | K5: =Time!K$10 -> 2 | L5: =Time!L$10 -> 3 | M5: =Time!M$10 -> 4 | N5: =Time!N$10 -> 5 | O5: =Time!O$10 -> 6 | P5: =Time!P$10 -> 7 | Q5: =Time!Q$10 -> 8 | ... CO5: =Time!CO$10 -> 84
A7: OPERATING REVENUE
B9: DEMAND FORECAST
E11: =InpS!E$8 -> Trains - domestic | F11: =InpS!F$8 -> 0 | G11: =InpS!G$8 -> trains | H11: =InpS!H$8 -> 2520 | I11: =InpS!I$8 -> 0 | J11: =InpS!J$8 -> 30 | K11: =InpS!K$8 -> 30 | L11: =InpS!L$8 -> 30 | ... CO11: =InpS!CO$8 -> 30
E12: =InpS!E$9 -> Trains - international | F12: =InpS!F$9 -> 0 | G12: =InpS!G$9 -> trains | H12: =InpS!H$9 -> 1326 | I12: =InpS!I$9 -> 0 | J12: =InpS!J$9 -> 10 | K12: =InpS!K$9 -> 12 | L12: =InpS!L$9 -> 12 | ... CO12: =InpS!CO$9 -> 16
E14: =InpS!E$11 -> Arrivals per train - domestic | F14: =InpS!F$11 -> 0 | G14: =InpS!G$11 -> arrivals / train | H14: =InpS!H$11 -> 0 | I14: =InpS!I$11 -> 0 | J14: =InpS!J$11 -> 370 | K14: =InpS!K$11 -> 350 | L14: =InpS!L$11 -> 370 | ... CO14: =InpS!CO$11 -> 370
E15: =InpS!E$12 -> Arrivals per train - international | F15: =InpS!F$12 -> 0 | G15: =InpS!G$12 -> arrivals / train | H15: =InpS!H$12 -> 0 | I15: =InpS!I$12 -> 0 | J15: =InpS!J$12 -> 34 | K15: =InpS!K$12 -> 34 | L15: =InpS!L$12 -> 34 | ... CO15: =InpS!CO$12 -> 44
E17: =Time!E$69 -> Forecast period flag | F17: =Time!F$69 -> 0 | G17: =Time!G$69 -> flag | H17: =Time!H$69 -> 80 | I17: =Time!I$69 -> 0 | J17: =Time!J$69 -> 0 | K17: =Time!K$69 -> 0 | L17: =Time!L$69 -> 1 | ... CO17: =Time!CO$69 -> 0
E19: Arrivals - Domestic | G19: arrivals | H19: =SUM(J19:CO19) -> 868800 | J19: =IF(J$17 = 1, J11 * J14, 0) -> 0 | K19: =IF(K$17 = 1, K11 * K14, 0) -> 0 | L19: =IF(L$17 = 1, L11 * L14, 0) -> 11100 | M19: =IF(M$17 = 1, M11 * M14, 0) -> 10500 | N19: =IF(N$17 = 1, N11 * N14, 0) -> 11100 | O19: =IF(O$17 = 1, O11 * O14, 0) -> 10500 | P19: =IF(P$17 = 1, P11 * P14, 0) -> 11100 | Q19: =IF(Q$17 = 1, Q11 * Q14, 0) -> 10500 | ... CO19: =IF(CO$17 = 1, CO11 * CO14, 0) -> 0
E20: Arrivals - International | G20: arrivals | H20: =SUM(J20:CO20) -> 55848 | J20: =IF(J$17 = 1, J12 * J15, 0) -> 0 | K20: =IF(K$17 = 1, K12 * K15, 0) -> 0 | L20: =IF(L$17 = 1, L12 * L15, 0) -> 408 | M20: =IF(M$17 = 1, M12 * M15, 0) -> 616 | N20: =IF(N$17 = 1, N12 * N15, 0) -> 616 | O20: =IF(O$17 = 1, O12 * O15, 0) -> 704 | P20: =IF(P$17 = 1, P12 * P15, 0) -> 704 | Q20: =IF(Q$17 = 1, Q12 * Q15, 0) -> 704 | ... CO20: =IF(CO$17 = 1, CO12 * CO15, 0) -> 0
E21: Arrivals | G21: arrivals | H21: =SUM(J21:CO21) -> 924648 | J21: =SUM(J19:J20) -> 0 | K21: =SUM(K19:K20) -> 0 | L21: =SUM(L19:L20) -> 11508 | M21: =SUM(M19:M20) -> 11116 | N21: =SUM(N19:N20) -> 11716 | O21: =SUM(O19:O20) -> 11204 | P21: =SUM(P19:P20) -> 11804 | Q21: =SUM(Q19:Q20) -> 11204 | ... CO21: =SUM(CO19:CO20) -> 0
E23: =InpC!E$31 -> Train capacity - domestic | F23: =InpC!F$31 -> 350 | G23: =InpC!G$31 -> seats
E24: =InpC!E$33 -> Train capacity - international | F24: =InpC!F$33 -> 150 | G24: =InpC!G$33 -> seats
E26: =InpS!E$14 -> Occupancy - domestic | F26: =InpS!F$14 -> 0 | G26: =InpS!G$14 -> % | H26: =InpS!H$14 -> 0 | I26: =InpS!I$14 -> 0 | J26: =InpS!J$14 -> 0.55 | K26: =InpS!K$14 -> 0.55 | L26: =InpS!L$14 -> 0.55 | ... CO26: =InpS!CO$14 -> 0.62
E27: =InpS!E$15 -> Occupancy - international | F27: =InpS!F$15 -> 0 | G27: =InpS!G$15 -> % | H27: =InpS!H$15 -> 0 | I27: =InpS!I$15 -> 0 | J27: =InpS!J$15 -> 0.45 | K27: =InpS!K$15 -> 0.45 | L27: =InpS!L$15 -> 0.45 | ... CO27: =InpS!CO$15 -> 0.55
E29: =E$19 -> Arrivals - Domestic | F29: =F$19 -> 0 | G29: =G$19 -> arrivals | H29: =H$19 -> 868800 | I29: =I$19 -> 0 | J29: =J$19 -> 0 | K29: =K$19 -> 0 | L29: =L$19 -> 11100 | ... CO29: =CO$19 -> 0
E30: =E$20 -> Arrivals - International | F30: =F$20 -> 0 | G30: =G$20 -> arrivals | H30: =H$20 -> 55848 | I30: =I$20 -> 0 | J30: =J$20 -> 0 | K30: =K$20 -> 0 | L30: =L$20 -> 408 | ... CO30: =CO$20 -> 0
E32: Passengers - domestic | G32: pax | H32: =SUM(J32:CO32) -> 181950300 | J32: =$F23 * J26 * J29 -> 0 | K32: =$F23 * K26 * K29 -> 0 | L32: =$F23 * L26 * L29 -> 2136750 | M32: =$F23 * M26 * M29 -> 2021250 | N32: =$F23 * N26 * N29 -> 2136750 | O32: =$F23 * O26 * O29 -> 2021250 | P32: =$F23 * P26 * P29 -> 2136750 | Q32: =$F23 * Q26 * Q29 -> 2021250 | ... CO32: =$F23 * CO26 * CO29 -> 0
E33: Passengers - international | G33: pax | H33: =SUM(J33:CO33) -> 4213260 | J33: =$F24 * J27 * J30 -> 0 | K33: =$F24 * K27 * K30 -> 0 | L33: =$F24 * L27 * L30 -> 27540 | M33: =$F24 * M27 * M30 -> 41580 | N33: =$F24 * N27 * N30 -> 41580 | O33: =$F24 * O27 * O30 -> 47520 | P33: =$F24 * P27 * P30 -> 47520 | Q33: =$F24 * Q27 * Q30 -> 47520 | ... CO33: =$F24 * CO27 * CO30 -> 0
E34: Passengers | G34: pax | H34: =SUM(J34:CO34) -> 186163560 | J34: =SUM(J32:J33) -> 0 | K34: =SUM(K32:K33) -> 0 | L34: =SUM(L32:L33) -> 2164290 | M34: =SUM(M32:M33) -> 2062830 | N34: =SUM(N32:N33) -> 2178330 | O34: =SUM(O32:O33) -> 2068770 | P34: =SUM(P32:P33) -> 2184270 | Q34: =SUM(Q32:Q33) -> 2068770 | ... CO34: =SUM(CO32:CO33) -> 0
B36: Operating revenue
E37: =InpC!E$35 -> Average fare per passenger | F37: =InpC!F$35 -> 7.15 | G37: =InpC!G$35 -> USD/pax
E38: =InpC!E$102 -> Unit in thousand | F38: =InpC!F$102 -> 1000 | G38: =InpC!G$102 -> units
E39: =E$34 -> Passengers | F39: =F$34 -> 0 | G39: =G$34 -> pax | H39: =H$34 -> 186163560 | I39: =I$34 -> 0 | J39: =J$34 -> 0 | K39: =K$34 -> 0 | L39: =L$34 -> 2164290 | ... CO39: =CO$34 -> 0
E40: =Esc!E$26 -> CPI escalation factor | F40: =Esc!F$26 -> 0 | G40: =Esc!G$26 -> factor | H40: =Esc!H$26 -> 0 | I40: =Esc!I$26 -> 0 | J40: =Esc!J$26 -> 0 | K40: =Esc!K$26 -> 1 | L40: =Esc!L$26 -> 1.0146738 | ... CO40: =Esc!CO$26 -> 1.9416902
E41: =Time!E$69 -> Forecast period flag | F41: =Time!F$69 -> 0 | G41: =Time!G$69 -> flag | H41: =Time!H$69 -> 80 | I41: =Time!I$69 -> 0 | J41: =Time!J$69 -> 0 | K41: =Time!K$69 -> 0 | L41: =Time!L$69 -> 1 | ... CO41: =Time!CO$69 -> 0
E42: Operating revenue | F42: IS | G42: =SMU -> $ 000s | H42: =SUM(J42:CO42) -> 1941568.6 | J42: =IF( J41 = 1,$F37 / $F38 * J39 * J40, 0) -> 0 | K42: =IF( K41 = 1,$F37 / $F38 * K39 * K40, 0) -> 0 | L42: =IF( L41 = 1,$F37 / $F38 * L39 * L40, 0) -> 15701.746 | M42: =IF( M41 = 1,$F37 / $F38 * M39 * M40, 0) -> 15185.266 | N42: =IF( N41 = 1,$F37 / $F38 * N39 * N40, 0) -> 16270.808 | O42: =IF( O41 = 1,$F37 / $F38 * O39 * O40, 0) -> 15679.208 | P42: =IF( P41 = 1,$F37 / $F38 * P39 * P40, 0) -> 16757.744 | Q42: =IF( Q41 = 1,$F37 / $F38 * Q39 * Q40, 0) -> 16066.407 | ... CO42: =IF( CO41 = 1,$F37 / $F38 * CO39 * CO40, 0) -> 0
A45: OPERATING REVENUE RECEIVED
E47: =InpC!E$37 -> Account receivables days | F47: =InpC!F$37 -> 25 | G47: =InpC!G$37 -> days
E48: =Time!E$30 -> Days in model period | F48: =Time!F$30 -> 0 | G48: =Time!G$30 -> days | H48: =Time!H$30 -> 0 | I48: =Time!I$30 -> 0 | J48: =Time!J$30 -> 92 | K48: =Time!K$30 -> 92 | L48: =Time!L$30 -> 90 | ... CO48: =Time!CO$30 -> 91
E49: =E$42 -> Operating revenue | F49: =F$42 -> IS | G49: =G$42 -> $ 000s | H49: =H$42 -> 1941568.6 | I49: =I$42 -> 0 | J49: =J$42 -> 0 | K49: =K$42 -> 0 | L49: =L$42 -> 15701.746 | ... CO49: =CO$42 -> 0
E50: Cash from paid invoices | G50: =SMU -> $ 000s | J50: =(J48 - $F47) / J48 * J49 -> 0 | K50: =(K48 - $F47) / K48 * K49 -> 0 | L50: =(L48 - $F47) / L48 * L49 -> 11340.15 | M50: =(M48 - $F47) / M48 * M49 -> 11013.49 | N50: =(N48 - $F47) / N48 * N49 -> 11849.393 | O50: =(O48 - $F47) / O48 * O49 -> 11418.554 | P50: =(P48 - $F47) / P48 * P49 -> 12102.815 | Q50: =(Q48 - $F47) / Q48 * Q49 -> 11652.559 | ... CO50: =(CO48 - $F47) / CO48 * CO49 -> 0
E52: =E$62 -> Account receivables balance BEG | F52: =F$62 -> 0 | G52: =G$62 -> $ 000s | H52: =H$62 -> 0 | I52: =I$62 -> 0 | J52: =J$62 -> 0 | K52: =K$62 -> 0 | L52: =L$62 -> 0 | ... CO52: =CO$62 -> 0
E53: =E$50 -> Cash from paid invoices | F53: =F$50 -> 0 | G53: =G$50 -> $ 000s | H53: =H$50 -> 0 | I53: =I$50 -> 0 | J53: =J$50 -> 0 | K53: =K$50 -> 0 | L53: =L$50 -> 11340.15 | ... CO53: =CO$50 -> 0
E54: Operating revenue received | F54: CF | G54: =SMU -> $ 000s | H54: =SUM(J54:CO54) -> 1941568.6 | J54: =SUM(J52:J53) -> 0 | K54: =SUM(K52:K53) -> 0 | L54: =SUM(L52:L53) -> 11340.15 | M54: =SUM(M52:M53) -> 15375.086 | N54: =SUM(N52:N53) -> 16021.169 | O54: =SUM(O52:O53) -> 15839.969 | P54: =SUM(P52:P53) -> 16363.469 | Q54: =SUM(Q52:Q53) -> 16307.488 | ... CO54: =SUM(CO52:CO53) -> 0
A57: ACCOUNT RECEIVABLES BALANCE
...

Sheet OpCost
A1: =RIGHT(CELL("filename", A1), LEN(CELL("filename", A1)) - SEARCH("]", CELL("filename", A1)))
